2020-06-18 00:09:30,466 ERROR scheduler Exception in Enqueue Events for Site VirtualOffice
Traceback (most recent call last):
  File "/home/ibrahim/frappe-bench/env/lib/python3.8/site-packages/pymysql/connections.py", line 581, in connect
    sock = socket.create_connection(
  File "/usr/lib/python3.8/socket.py", line 787, in create_connection
    for res in getaddrinfo(host, port, 0, SOCK_STREAM):
  File "/usr/lib/python3.8/socket.py", line 918, in getaddrinfo
    for res in _socket.getaddrinfo(host, port, family, type, proto, flags):
socket.gaierror: [Errno -3] Temporary failure in name resolution

During handling of the above exception, another exception occurred:

Traceback (most recent call last):
  File "/home/ibrahim/frappe-bench/apps/frappe/frappe/utils/scheduler.py", line 64, in enqueue_events_for_site
    if is_scheduler_inactive():
  File "/home/ibrahim/frappe-bench/apps/frappe/frappe/utils/scheduler.py", line 97, in is_scheduler_inactive
    if is_scheduler_disabled():
  File "/home/ibrahim/frappe-bench/apps/frappe/frappe/utils/scheduler.py", line 106, in is_scheduler_disabled
    return not frappe.utils.cint(frappe.db.get_single_value("System Settings", "enable_scheduler"))
  File "/home/ibrahim/frappe-bench/apps/frappe/frappe/database/database.py", line 559, in get_single_value
    val = self.sql("""select `value` from
  File "/home/ibrahim/frappe-bench/apps/frappe/frappe/database/database.py", line 122, in sql
    self.connect()
  File "/home/ibrahim/frappe-bench/apps/frappe/frappe/database/database.py", line 75, in connect
    self._conn = self.get_connection()
  File "/home/ibrahim/frappe-bench/apps/frappe/frappe/database/mariadb/database.py", line 89, in get_connection
    conn = pymysql.connect(self.host, self.user or '', self.password or '',
  File "/home/ibrahim/frappe-bench/env/lib/python3.8/site-packages/pymysql/__init__.py", line 94, in Connect
    return Connection(*args, **kwargs)
  File "/home/ibrahim/frappe-bench/env/lib/python3.8/site-packages/pymysql/connections.py", line 325, in __init__
    self.connect()
  File "/home/ibrahim/frappe-bench/env/lib/python3.8/site-packages/pymysql/connections.py", line 630, in connect
    raise exc
pymysql.err.OperationalError: (2003, "Can't connect to MySQL server on 'library' ([Errno -3] Temporary failure in name resolution)")

2020-06-18 00:09:30,526 ERROR scheduler Exception in Enqueue Events for Site workie
Traceback (most recent call last):
  File "/home/ibrahim/frappe-bench/env/lib/python3.8/site-packages/pymysql/connections.py", line 581, in connect
    sock = socket.create_connection(
  File "/usr/lib/python3.8/socket.py", line 787, in create_connection
    for res in getaddrinfo(host, port, 0, SOCK_STREAM):
  File "/usr/lib/python3.8/socket.py", line 918, in getaddrinfo
    for res in _socket.getaddrinfo(host, port, family, type, proto, flags):
socket.gaierror: [Errno -3] Temporary failure in name resolution

During handling of the above exception, another exception occurred:

Traceback (most recent call last):
  File "/home/ibrahim/frappe-bench/apps/frappe/frappe/utils/scheduler.py", line 64, in enqueue_events_for_site
    if is_scheduler_inactive():
  File "/home/ibrahim/frappe-bench/apps/frappe/frappe/utils/scheduler.py", line 97, in is_scheduler_inactive
    if is_scheduler_disabled():
  File "/home/ibrahim/frappe-bench/apps/frappe/frappe/utils/scheduler.py", line 106, in is_scheduler_disabled
    return not frappe.utils.cint(frappe.db.get_single_value("System Settings", "enable_scheduler"))
  File "/home/ibrahim/frappe-bench/apps/frappe/frappe/database/database.py", line 559, in get_single_value
    val = self.sql("""select `value` from
  File "/home/ibrahim/frappe-bench/apps/frappe/frappe/database/database.py", line 122, in sql
    self.connect()
  File "/home/ibrahim/frappe-bench/apps/frappe/frappe/database/database.py", line 75, in connect
    self._conn = self.get_connection()
  File "/home/ibrahim/frappe-bench/apps/frappe/frappe/database/mariadb/database.py", line 89, in get_connection
    conn = pymysql.connect(self.host, self.user or '', self.password or '',
  File "/home/ibrahim/frappe-bench/env/lib/python3.8/site-packages/pymysql/__init__.py", line 94, in Connect
    return Connection(*args, **kwargs)
  File "/home/ibrahim/frappe-bench/env/lib/python3.8/site-packages/pymysql/connections.py", line 325, in __init__
    self.connect()
  File "/home/ibrahim/frappe-bench/env/lib/python3.8/site-packages/pymysql/connections.py", line 630, in connect
    raise exc
pymysql.err.OperationalError: (2003, "Can't connect to MySQL server on 'library' ([Errno -3] Temporary failure in name resolution)")

2020-06-18 00:10:31,162 ERROR scheduler Exception in Enqueue Events for Site VirtualOffice
Traceback (most recent call last):
  File "/home/ibrahim/frappe-bench/env/lib/python3.8/site-packages/pymysql/connections.py", line 581, in connect
    sock = socket.create_connection(
  File "/usr/lib/python3.8/socket.py", line 787, in create_connection
    for res in getaddrinfo(host, port, 0, SOCK_STREAM):
  File "/usr/lib/python3.8/socket.py", line 918, in getaddrinfo
    for res in _socket.getaddrinfo(host, port, family, type, proto, flags):
socket.gaierror: [Errno -3] Temporary failure in name resolution

During handling of the above exception, another exception occurred:

Traceback (most recent call last):
  File "/home/ibrahim/frappe-bench/apps/frappe/frappe/utils/scheduler.py", line 64, in enqueue_events_for_site
    if is_scheduler_inactive():
  File "/home/ibrahim/frappe-bench/apps/frappe/frappe/utils/scheduler.py", line 97, in is_scheduler_inactive
    if is_scheduler_disabled():
  File "/home/ibrahim/frappe-bench/apps/frappe/frappe/utils/scheduler.py", line 106, in is_scheduler_disabled
    return not frappe.utils.cint(frappe.db.get_single_value("System Settings", "enable_scheduler"))
  File "/home/ibrahim/frappe-bench/apps/frappe/frappe/database/database.py", line 559, in get_single_value
    val = self.sql("""select `value` from
  File "/home/ibrahim/frappe-bench/apps/frappe/frappe/database/database.py", line 122, in sql
    self.connect()
  File "/home/ibrahim/frappe-bench/apps/frappe/frappe/database/database.py", line 75, in connect
    self._conn = self.get_connection()
  File "/home/ibrahim/frappe-bench/apps/frappe/frappe/database/mariadb/database.py", line 89, in get_connection
    conn = pymysql.connect(self.host, self.user or '', self.password or '',
  File "/home/ibrahim/frappe-bench/env/lib/python3.8/site-packages/pymysql/__init__.py", line 94, in Connect
    return Connection(*args, **kwargs)
  File "/home/ibrahim/frappe-bench/env/lib/python3.8/site-packages/pymysql/connections.py", line 325, in __init__
    self.connect()
  File "/home/ibrahim/frappe-bench/env/lib/python3.8/site-packages/pymysql/connections.py", line 630, in connect
    raise exc
pymysql.err.OperationalError: (2003, "Can't connect to MySQL server on 'library' ([Errno -3] Temporary failure in name resolution)")

2020-06-18 00:10:31,213 ERROR scheduler Exception in Enqueue Events for Site workie
Traceback (most recent call last):
  File "/home/ibrahim/frappe-bench/env/lib/python3.8/site-packages/pymysql/connections.py", line 581, in connect
    sock = socket.create_connection(
  File "/usr/lib/python3.8/socket.py", line 787, in create_connection
    for res in getaddrinfo(host, port, 0, SOCK_STREAM):
  File "/usr/lib/python3.8/socket.py", line 918, in getaddrinfo
    for res in _socket.getaddrinfo(host, port, family, type, proto, flags):
socket.gaierror: [Errno -3] Temporary failure in name resolution

During handling of the above exception, another exception occurred:

Traceback (most recent call last):
  File "/home/ibrahim/frappe-bench/apps/frappe/frappe/utils/scheduler.py", line 64, in enqueue_events_for_site
    if is_scheduler_inactive():
  File "/home/ibrahim/frappe-bench/apps/frappe/frappe/utils/scheduler.py", line 97, in is_scheduler_inactive
    if is_scheduler_disabled():
  File "/home/ibrahim/frappe-bench/apps/frappe/frappe/utils/scheduler.py", line 106, in is_scheduler_disabled
    return not frappe.utils.cint(frappe.db.get_single_value("System Settings", "enable_scheduler"))
  File "/home/ibrahim/frappe-bench/apps/frappe/frappe/database/database.py", line 559, in get_single_value
    val = self.sql("""select `value` from
  File "/home/ibrahim/frappe-bench/apps/frappe/frappe/database/database.py", line 122, in sql
    self.connect()
  File "/home/ibrahim/frappe-bench/apps/frappe/frappe/database/database.py", line 75, in connect
    self._conn = self.get_connection()
  File "/home/ibrahim/frappe-bench/apps/frappe/frappe/database/mariadb/database.py", line 89, in get_connection
    conn = pymysql.connect(self.host, self.user or '', self.password or '',
  File "/home/ibrahim/frappe-bench/env/lib/python3.8/site-packages/pymysql/__init__.py", line 94, in Connect
    return Connection(*args, **kwargs)
  File "/home/ibrahim/frappe-bench/env/lib/python3.8/site-packages/pymysql/connections.py", line 325, in __init__
    self.connect()
  File "/home/ibrahim/frappe-bench/env/lib/python3.8/site-packages/pymysql/connections.py", line 630, in connect
    raise exc
pymysql.err.OperationalError: (2003, "Can't connect to MySQL server on 'library' ([Errno -3] Temporary failure in name resolution)")

2020-06-18 00:11:31,339 ERROR scheduler Exception in Enqueue Events for Site VirtualOffice
Traceback (most recent call last):
  File "/home/ibrahim/frappe-bench/env/lib/python3.8/site-packages/pymysql/connections.py", line 581, in connect
    sock = socket.create_connection(
  File "/usr/lib/python3.8/socket.py", line 787, in create_connection
    for res in getaddrinfo(host, port, 0, SOCK_STREAM):
  File "/usr/lib/python3.8/socket.py", line 918, in getaddrinfo
    for res in _socket.getaddrinfo(host, port, family, type, proto, flags):
socket.gaierror: [Errno -3] Temporary failure in name resolution

During handling of the above exception, another exception occurred:

Traceback (most recent call last):
  File "/home/ibrahim/frappe-bench/apps/frappe/frappe/utils/scheduler.py", line 64, in enqueue_events_for_site
    if is_scheduler_inactive():
  File "/home/ibrahim/frappe-bench/apps/frappe/frappe/utils/scheduler.py", line 97, in is_scheduler_inactive
    if is_scheduler_disabled():
  File "/home/ibrahim/frappe-bench/apps/frappe/frappe/utils/scheduler.py", line 106, in is_scheduler_disabled
    return not frappe.utils.cint(frappe.db.get_single_value("System Settings", "enable_scheduler"))
  File "/home/ibrahim/frappe-bench/apps/frappe/frappe/database/database.py", line 559, in get_single_value
    val = self.sql("""select `value` from
  File "/home/ibrahim/frappe-bench/apps/frappe/frappe/database/database.py", line 122, in sql
    self.connect()
  File "/home/ibrahim/frappe-bench/apps/frappe/frappe/database/database.py", line 75, in connect
    self._conn = self.get_connection()
  File "/home/ibrahim/frappe-bench/apps/frappe/frappe/database/mariadb/database.py", line 89, in get_connection
    conn = pymysql.connect(self.host, self.user or '', self.password or '',
  File "/home/ibrahim/frappe-bench/env/lib/python3.8/site-packages/pymysql/__init__.py", line 94, in Connect
    return Connection(*args, **kwargs)
  File "/home/ibrahim/frappe-bench/env/lib/python3.8/site-packages/pymysql/connections.py", line 325, in __init__
    self.connect()
  File "/home/ibrahim/frappe-bench/env/lib/python3.8/site-packages/pymysql/connections.py", line 630, in connect
    raise exc
pymysql.err.OperationalError: (2003, "Can't connect to MySQL server on 'library' ([Errno -3] Temporary failure in name resolution)")

2020-06-18 00:11:31,343 ERROR scheduler Exception in Enqueue Events for Site workie
Traceback (most recent call last):
  File "/home/ibrahim/frappe-bench/env/lib/python3.8/site-packages/pymysql/connections.py", line 581, in connect
    sock = socket.create_connection(
  File "/usr/lib/python3.8/socket.py", line 787, in create_connection
    for res in getaddrinfo(host, port, 0, SOCK_STREAM):
  File "/usr/lib/python3.8/socket.py", line 918, in getaddrinfo
    for res in _socket.getaddrinfo(host, port, family, type, proto, flags):
socket.gaierror: [Errno -3] Temporary failure in name resolution

During handling of the above exception, another exception occurred:

Traceback (most recent call last):
  File "/home/ibrahim/frappe-bench/apps/frappe/frappe/utils/scheduler.py", line 64, in enqueue_events_for_site
    if is_scheduler_inactive():
  File "/home/ibrahim/frappe-bench/apps/frappe/frappe/utils/scheduler.py", line 97, in is_scheduler_inactive
    if is_scheduler_disabled():
  File "/home/ibrahim/frappe-bench/apps/frappe/frappe/utils/scheduler.py", line 106, in is_scheduler_disabled
    return not frappe.utils.cint(frappe.db.get_single_value("System Settings", "enable_scheduler"))
  File "/home/ibrahim/frappe-bench/apps/frappe/frappe/database/database.py", line 559, in get_single_value
    val = self.sql("""select `value` from
  File "/home/ibrahim/frappe-bench/apps/frappe/frappe/database/database.py", line 122, in sql
    self.connect()
  File "/home/ibrahim/frappe-bench/apps/frappe/frappe/database/database.py", line 75, in connect
    self._conn = self.get_connection()
  File "/home/ibrahim/frappe-bench/apps/frappe/frappe/database/mariadb/database.py", line 89, in get_connection
    conn = pymysql.connect(self.host, self.user or '', self.password or '',
  File "/home/ibrahim/frappe-bench/env/lib/python3.8/site-packages/pymysql/__init__.py", line 94, in Connect
    return Connection(*args, **kwargs)
  File "/home/ibrahim/frappe-bench/env/lib/python3.8/site-packages/pymysql/connections.py", line 325, in __init__
    self.connect()
  File "/home/ibrahim/frappe-bench/env/lib/python3.8/site-packages/pymysql/connections.py", line 630, in connect
    raise exc
pymysql.err.OperationalError: (2003, "Can't connect to MySQL server on 'library' ([Errno -3] Temporary failure in name resolution)")

2020-06-18 00:12:31,405 ERROR scheduler Exception in Enqueue Events for Site VirtualOffice
Traceback (most recent call last):
  File "/home/ibrahim/frappe-bench/env/lib/python3.8/site-packages/pymysql/connections.py", line 581, in connect
    sock = socket.create_connection(
  File "/usr/lib/python3.8/socket.py", line 787, in create_connection
    for res in getaddrinfo(host, port, 0, SOCK_STREAM):
  File "/usr/lib/python3.8/socket.py", line 918, in getaddrinfo
    for res in _socket.getaddrinfo(host, port, family, type, proto, flags):
socket.gaierror: [Errno -3] Temporary failure in name resolution

During handling of the above exception, another exception occurred:

Traceback (most recent call last):
  File "/home/ibrahim/frappe-bench/apps/frappe/frappe/utils/scheduler.py", line 64, in enqueue_events_for_site
    if is_scheduler_inactive():
  File "/home/ibrahim/frappe-bench/apps/frappe/frappe/utils/scheduler.py", line 97, in is_scheduler_inactive
    if is_scheduler_disabled():
  File "/home/ibrahim/frappe-bench/apps/frappe/frappe/utils/scheduler.py", line 106, in is_scheduler_disabled
    return not frappe.utils.cint(frappe.db.get_single_value("System Settings", "enable_scheduler"))
  File "/home/ibrahim/frappe-bench/apps/frappe/frappe/database/database.py", line 559, in get_single_value
    val = self.sql("""select `value` from
  File "/home/ibrahim/frappe-bench/apps/frappe/frappe/database/database.py", line 122, in sql
    self.connect()
  File "/home/ibrahim/frappe-bench/apps/frappe/frappe/database/database.py", line 75, in connect
    self._conn = self.get_connection()
  File "/home/ibrahim/frappe-bench/apps/frappe/frappe/database/mariadb/database.py", line 89, in get_connection
    conn = pymysql.connect(self.host, self.user or '', self.password or '',
  File "/home/ibrahim/frappe-bench/env/lib/python3.8/site-packages/pymysql/__init__.py", line 94, in Connect
    return Connection(*args, **kwargs)
  File "/home/ibrahim/frappe-bench/env/lib/python3.8/site-packages/pymysql/connections.py", line 325, in __init__
    self.connect()
  File "/home/ibrahim/frappe-bench/env/lib/python3.8/site-packages/pymysql/connections.py", line 630, in connect
    raise exc
pymysql.err.OperationalError: (2003, "Can't connect to MySQL server on 'library' ([Errno -3] Temporary failure in name resolution)")

2020-06-18 00:12:31,406 ERROR scheduler Exception in Enqueue Events for Site workie
Traceback (most recent call last):
  File "/home/ibrahim/frappe-bench/env/lib/python3.8/site-packages/pymysql/connections.py", line 581, in connect
    sock = socket.create_connection(
  File "/usr/lib/python3.8/socket.py", line 787, in create_connection
    for res in getaddrinfo(host, port, 0, SOCK_STREAM):
  File "/usr/lib/python3.8/socket.py", line 918, in getaddrinfo
    for res in _socket.getaddrinfo(host, port, family, type, proto, flags):
socket.gaierror: [Errno -3] Temporary failure in name resolution

During handling of the above exception, another exception occurred:

Traceback (most recent call last):
  File "/home/ibrahim/frappe-bench/apps/frappe/frappe/utils/scheduler.py", line 64, in enqueue_events_for_site
    if is_scheduler_inactive():
  File "/home/ibrahim/frappe-bench/apps/frappe/frappe/utils/scheduler.py", line 97, in is_scheduler_inactive
    if is_scheduler_disabled():
  File "/home/ibrahim/frappe-bench/apps/frappe/frappe/utils/scheduler.py", line 106, in is_scheduler_disabled
    return not frappe.utils.cint(frappe.db.get_single_value("System Settings", "enable_scheduler"))
  File "/home/ibrahim/frappe-bench/apps/frappe/frappe/database/database.py", line 559, in get_single_value
    val = self.sql("""select `value` from
  File "/home/ibrahim/frappe-bench/apps/frappe/frappe/database/database.py", line 122, in sql
    self.connect()
  File "/home/ibrahim/frappe-bench/apps/frappe/frappe/database/database.py", line 75, in connect
    self._conn = self.get_connection()
  File "/home/ibrahim/frappe-bench/apps/frappe/frappe/database/mariadb/database.py", line 89, in get_connection
    conn = pymysql.connect(self.host, self.user or '', self.password or '',
  File "/home/ibrahim/frappe-bench/env/lib/python3.8/site-packages/pymysql/__init__.py", line 94, in Connect
    return Connection(*args, **kwargs)
  File "/home/ibrahim/frappe-bench/env/lib/python3.8/site-packages/pymysql/connections.py", line 325, in __init__
    self.connect()
  File "/home/ibrahim/frappe-bench/env/lib/python3.8/site-packages/pymysql/connections.py", line 630, in connect
    raise exc
pymysql.err.OperationalError: (2003, "Can't connect to MySQL server on 'library' ([Errno -3] Temporary failure in name resolution)")

2020-06-18 00:13:33,680 ERROR scheduler Exception in Enqueue Events for Site VirtualOffice
Traceback (most recent call last):
  File "/home/ibrahim/frappe-bench/env/lib/python3.8/site-packages/pymysql/connections.py", line 581, in connect
    sock = socket.create_connection(
  File "/usr/lib/python3.8/socket.py", line 787, in create_connection
    for res in getaddrinfo(host, port, 0, SOCK_STREAM):
  File "/usr/lib/python3.8/socket.py", line 918, in getaddrinfo
    for res in _socket.getaddrinfo(host, port, family, type, proto, flags):
socket.gaierror: [Errno -3] Temporary failure in name resolution

During handling of the above exception, another exception occurred:

Traceback (most recent call last):
  File "/home/ibrahim/frappe-bench/apps/frappe/frappe/utils/scheduler.py", line 64, in enqueue_events_for_site
    if is_scheduler_inactive():
  File "/home/ibrahim/frappe-bench/apps/frappe/frappe/utils/scheduler.py", line 97, in is_scheduler_inactive
    if is_scheduler_disabled():
  File "/home/ibrahim/frappe-bench/apps/frappe/frappe/utils/scheduler.py", line 106, in is_scheduler_disabled
    return not frappe.utils.cint(frappe.db.get_single_value("System Settings", "enable_scheduler"))
  File "/home/ibrahim/frappe-bench/apps/frappe/frappe/database/database.py", line 559, in get_single_value
    val = self.sql("""select `value` from
  File "/home/ibrahim/frappe-bench/apps/frappe/frappe/database/database.py", line 122, in sql
    self.connect()
  File "/home/ibrahim/frappe-bench/apps/frappe/frappe/database/database.py", line 75, in connect
    self._conn = self.get_connection()
  File "/home/ibrahim/frappe-bench/apps/frappe/frappe/database/mariadb/database.py", line 89, in get_connection
    conn = pymysql.connect(self.host, self.user or '', self.password or '',
  File "/home/ibrahim/frappe-bench/env/lib/python3.8/site-packages/pymysql/__init__.py", line 94, in Connect
    return Connection(*args, **kwargs)
  File "/home/ibrahim/frappe-bench/env/lib/python3.8/site-packages/pymysql/connections.py", line 325, in __init__
    self.connect()
  File "/home/ibrahim/frappe-bench/env/lib/python3.8/site-packages/pymysql/connections.py", line 630, in connect
    raise exc
pymysql.err.OperationalError: (2003, "Can't connect to MySQL server on 'library' ([Errno -3] Temporary failure in name resolution)")

2020-06-18 00:13:34,132 ERROR scheduler Exception in Enqueue Events for Site workie
Traceback (most recent call last):
  File "/home/ibrahim/frappe-bench/env/lib/python3.8/site-packages/pymysql/connections.py", line 581, in connect
    sock = socket.create_connection(
  File "/usr/lib/python3.8/socket.py", line 787, in create_connection
    for res in getaddrinfo(host, port, 0, SOCK_STREAM):
  File "/usr/lib/python3.8/socket.py", line 918, in getaddrinfo
    for res in _socket.getaddrinfo(host, port, family, type, proto, flags):
socket.gaierror: [Errno -3] Temporary failure in name resolution

During handling of the above exception, another exception occurred:

Traceback (most recent call last):
  File "/home/ibrahim/frappe-bench/apps/frappe/frappe/utils/scheduler.py", line 64, in enqueue_events_for_site
    if is_scheduler_inactive():
  File "/home/ibrahim/frappe-bench/apps/frappe/frappe/utils/scheduler.py", line 97, in is_scheduler_inactive
    if is_scheduler_disabled():
  File "/home/ibrahim/frappe-bench/apps/frappe/frappe/utils/scheduler.py", line 106, in is_scheduler_disabled
    return not frappe.utils.cint(frappe.db.get_single_value("System Settings", "enable_scheduler"))
  File "/home/ibrahim/frappe-bench/apps/frappe/frappe/database/database.py", line 559, in get_single_value
    val = self.sql("""select `value` from
  File "/home/ibrahim/frappe-bench/apps/frappe/frappe/database/database.py", line 122, in sql
    self.connect()
  File "/home/ibrahim/frappe-bench/apps/frappe/frappe/database/database.py", line 75, in connect
    self._conn = self.get_connection()
  File "/home/ibrahim/frappe-bench/apps/frappe/frappe/database/mariadb/database.py", line 89, in get_connection
    conn = pymysql.connect(self.host, self.user or '', self.password or '',
  File "/home/ibrahim/frappe-bench/env/lib/python3.8/site-packages/pymysql/__init__.py", line 94, in Connect
    return Connection(*args, **kwargs)
  File "/home/ibrahim/frappe-bench/env/lib/python3.8/site-packages/pymysql/connections.py", line 325, in __init__
    self.connect()
  File "/home/ibrahim/frappe-bench/env/lib/python3.8/site-packages/pymysql/connections.py", line 630, in connect
    raise exc
pymysql.err.OperationalError: (2003, "Can't connect to MySQL server on 'library' ([Errno -3] Temporary failure in name resolution)")

2020-06-18 00:14:34,320 ERROR scheduler Exception in Enqueue Events for Site VirtualOffice
Traceback (most recent call last):
  File "/home/ibrahim/frappe-bench/env/lib/python3.8/site-packages/pymysql/connections.py", line 581, in connect
    sock = socket.create_connection(
  File "/usr/lib/python3.8/socket.py", line 787, in create_connection
    for res in getaddrinfo(host, port, 0, SOCK_STREAM):
  File "/usr/lib/python3.8/socket.py", line 918, in getaddrinfo
    for res in _socket.getaddrinfo(host, port, family, type, proto, flags):
socket.gaierror: [Errno -3] Temporary failure in name resolution

During handling of the above exception, another exception occurred:

Traceback (most recent call last):
  File "/home/ibrahim/frappe-bench/apps/frappe/frappe/utils/scheduler.py", line 64, in enqueue_events_for_site
    if is_scheduler_inactive():
  File "/home/ibrahim/frappe-bench/apps/frappe/frappe/utils/scheduler.py", line 97, in is_scheduler_inactive
    if is_scheduler_disabled():
  File "/home/ibrahim/frappe-bench/apps/frappe/frappe/utils/scheduler.py", line 106, in is_scheduler_disabled
    return not frappe.utils.cint(frappe.db.get_single_value("System Settings", "enable_scheduler"))
  File "/home/ibrahim/frappe-bench/apps/frappe/frappe/database/database.py", line 559, in get_single_value
    val = self.sql("""select `value` from
  File "/home/ibrahim/frappe-bench/apps/frappe/frappe/database/database.py", line 122, in sql
    self.connect()
  File "/home/ibrahim/frappe-bench/apps/frappe/frappe/database/database.py", line 75, in connect
    self._conn = self.get_connection()
  File "/home/ibrahim/frappe-bench/apps/frappe/frappe/database/mariadb/database.py", line 89, in get_connection
    conn = pymysql.connect(self.host, self.user or '', self.password or '',
  File "/home/ibrahim/frappe-bench/env/lib/python3.8/site-packages/pymysql/__init__.py", line 94, in Connect
    return Connection(*args, **kwargs)
  File "/home/ibrahim/frappe-bench/env/lib/python3.8/site-packages/pymysql/connections.py", line 325, in __init__
    self.connect()
  File "/home/ibrahim/frappe-bench/env/lib/python3.8/site-packages/pymysql/connections.py", line 630, in connect
    raise exc
pymysql.err.OperationalError: (2003, "Can't connect to MySQL server on 'library' ([Errno -3] Temporary failure in name resolution)")

2020-06-18 00:14:34,430 ERROR scheduler Exception in Enqueue Events for Site workie
Traceback (most recent call last):
  File "/home/ibrahim/frappe-bench/env/lib/python3.8/site-packages/pymysql/connections.py", line 581, in connect
    sock = socket.create_connection(
  File "/usr/lib/python3.8/socket.py", line 787, in create_connection
    for res in getaddrinfo(host, port, 0, SOCK_STREAM):
  File "/usr/lib/python3.8/socket.py", line 918, in getaddrinfo
    for res in _socket.getaddrinfo(host, port, family, type, proto, flags):
socket.gaierror: [Errno -3] Temporary failure in name resolution

During handling of the above exception, another exception occurred:

Traceback (most recent call last):
  File "/home/ibrahim/frappe-bench/apps/frappe/frappe/utils/scheduler.py", line 64, in enqueue_events_for_site
    if is_scheduler_inactive():
  File "/home/ibrahim/frappe-bench/apps/frappe/frappe/utils/scheduler.py", line 97, in is_scheduler_inactive
    if is_scheduler_disabled():
  File "/home/ibrahim/frappe-bench/apps/frappe/frappe/utils/scheduler.py", line 106, in is_scheduler_disabled
    return not frappe.utils.cint(frappe.db.get_single_value("System Settings", "enable_scheduler"))
  File "/home/ibrahim/frappe-bench/apps/frappe/frappe/database/database.py", line 559, in get_single_value
    val = self.sql("""select `value` from
  File "/home/ibrahim/frappe-bench/apps/frappe/frappe/database/database.py", line 122, in sql
    self.connect()
  File "/home/ibrahim/frappe-bench/apps/frappe/frappe/database/database.py", line 75, in connect
    self._conn = self.get_connection()
  File "/home/ibrahim/frappe-bench/apps/frappe/frappe/database/mariadb/database.py", line 89, in get_connection
    conn = pymysql.connect(self.host, self.user or '', self.password or '',
  File "/home/ibrahim/frappe-bench/env/lib/python3.8/site-packages/pymysql/__init__.py", line 94, in Connect
    return Connection(*args, **kwargs)
  File "/home/ibrahim/frappe-bench/env/lib/python3.8/site-packages/pymysql/connections.py", line 325, in __init__
    self.connect()
  File "/home/ibrahim/frappe-bench/env/lib/python3.8/site-packages/pymysql/connections.py", line 630, in connect
    raise exc
pymysql.err.OperationalError: (2003, "Can't connect to MySQL server on 'library' ([Errno -3] Temporary failure in name resolution)")

2020-06-18 00:15:34,534 ERROR scheduler Exception in Enqueue Events for Site VirtualOffice
Traceback (most recent call last):
  File "/home/ibrahim/frappe-bench/env/lib/python3.8/site-packages/pymysql/connections.py", line 581, in connect
    sock = socket.create_connection(
  File "/usr/lib/python3.8/socket.py", line 787, in create_connection
    for res in getaddrinfo(host, port, 0, SOCK_STREAM):
  File "/usr/lib/python3.8/socket.py", line 918, in getaddrinfo
    for res in _socket.getaddrinfo(host, port, family, type, proto, flags):
socket.gaierror: [Errno -3] Temporary failure in name resolution

During handling of the above exception, another exception occurred:

Traceback (most recent call last):
  File "/home/ibrahim/frappe-bench/apps/frappe/frappe/utils/scheduler.py", line 64, in enqueue_events_for_site
    if is_scheduler_inactive():
  File "/home/ibrahim/frappe-bench/apps/frappe/frappe/utils/scheduler.py", line 97, in is_scheduler_inactive
    if is_scheduler_disabled():
  File "/home/ibrahim/frappe-bench/apps/frappe/frappe/utils/scheduler.py", line 106, in is_scheduler_disabled
    return not frappe.utils.cint(frappe.db.get_single_value("System Settings", "enable_scheduler"))
  File "/home/ibrahim/frappe-bench/apps/frappe/frappe/database/database.py", line 559, in get_single_value
    val = self.sql("""select `value` from
  File "/home/ibrahim/frappe-bench/apps/frappe/frappe/database/database.py", line 122, in sql
    self.connect()
  File "/home/ibrahim/frappe-bench/apps/frappe/frappe/database/database.py", line 75, in connect
    self._conn = self.get_connection()
  File "/home/ibrahim/frappe-bench/apps/frappe/frappe/database/mariadb/database.py", line 89, in get_connection
    conn = pymysql.connect(self.host, self.user or '', self.password or '',
  File "/home/ibrahim/frappe-bench/env/lib/python3.8/site-packages/pymysql/__init__.py", line 94, in Connect
    return Connection(*args, **kwargs)
  File "/home/ibrahim/frappe-bench/env/lib/python3.8/site-packages/pymysql/connections.py", line 325, in __init__
    self.connect()
  File "/home/ibrahim/frappe-bench/env/lib/python3.8/site-packages/pymysql/connections.py", line 630, in connect
    raise exc
pymysql.err.OperationalError: (2003, "Can't connect to MySQL server on 'library' ([Errno -3] Temporary failure in name resolution)")

2020-06-18 00:15:34,535 ERROR scheduler Exception in Enqueue Events for Site workie
Traceback (most recent call last):
  File "/home/ibrahim/frappe-bench/env/lib/python3.8/site-packages/pymysql/connections.py", line 581, in connect
    sock = socket.create_connection(
  File "/usr/lib/python3.8/socket.py", line 787, in create_connection
    for res in getaddrinfo(host, port, 0, SOCK_STREAM):
  File "/usr/lib/python3.8/socket.py", line 918, in getaddrinfo
    for res in _socket.getaddrinfo(host, port, family, type, proto, flags):
socket.gaierror: [Errno -3] Temporary failure in name resolution

During handling of the above exception, another exception occurred:

Traceback (most recent call last):
  File "/home/ibrahim/frappe-bench/apps/frappe/frappe/utils/scheduler.py", line 64, in enqueue_events_for_site
    if is_scheduler_inactive():
  File "/home/ibrahim/frappe-bench/apps/frappe/frappe/utils/scheduler.py", line 97, in is_scheduler_inactive
    if is_scheduler_disabled():
  File "/home/ibrahim/frappe-bench/apps/frappe/frappe/utils/scheduler.py", line 106, in is_scheduler_disabled
    return not frappe.utils.cint(frappe.db.get_single_value("System Settings", "enable_scheduler"))
  File "/home/ibrahim/frappe-bench/apps/frappe/frappe/database/database.py", line 559, in get_single_value
    val = self.sql("""select `value` from
  File "/home/ibrahim/frappe-bench/apps/frappe/frappe/database/database.py", line 122, in sql
    self.connect()
  File "/home/ibrahim/frappe-bench/apps/frappe/frappe/database/database.py", line 75, in connect
    self._conn = self.get_connection()
  File "/home/ibrahim/frappe-bench/apps/frappe/frappe/database/mariadb/database.py", line 89, in get_connection
    conn = pymysql.connect(self.host, self.user or '', self.password or '',
  File "/home/ibrahim/frappe-bench/env/lib/python3.8/site-packages/pymysql/__init__.py", line 94, in Connect
    return Connection(*args, **kwargs)
  File "/home/ibrahim/frappe-bench/env/lib/python3.8/site-packages/pymysql/connections.py", line 325, in __init__
    self.connect()
  File "/home/ibrahim/frappe-bench/env/lib/python3.8/site-packages/pymysql/connections.py", line 630, in connect
    raise exc
pymysql.err.OperationalError: (2003, "Can't connect to MySQL server on 'library' ([Errno -3] Temporary failure in name resolution)")

