2020-06-16 09:59:46,941 ERROR scheduler Exception in Enqueue Events for Site library
Traceback (most recent call last):
  File "/home/ibrahim/frappe-bench/env/lib/python3.8/site-packages/pymysql/connections.py", line 581, in connect
    sock = socket.create_connection(
  File "/usr/lib/python3.8/socket.py", line 787, in create_connection
    for res in getaddrinfo(host, port, 0, SOCK_STREAM):
  File "/usr/lib/python3.8/socket.py", line 918, in getaddrinfo
    for res in _socket.getaddrinfo(host, port, family, type, proto, flags):
socket.gaierror: [Errno -3] Temporary failure in name resolution

During handling of the above exception, another exception occurred:

Traceback (most recent call last):
  File "/home/ibrahim/frappe-bench/apps/frappe/frappe/utils/scheduler.py", line 64, in enqueue_events_for_site
    if is_scheduler_inactive():
  File "/home/ibrahim/frappe-bench/apps/frappe/frappe/utils/scheduler.py", line 97, in is_scheduler_inactive
    if is_scheduler_disabled():
  File "/home/ibrahim/frappe-bench/apps/frappe/frappe/utils/scheduler.py", line 106, in is_scheduler_disabled
    return not frappe.utils.cint(frappe.db.get_single_value("System Settings", "enable_scheduler"))
  File "/home/ibrahim/frappe-bench/apps/frappe/frappe/database/database.py", line 559, in get_single_value
    val = self.sql("""select `value` from
  File "/home/ibrahim/frappe-bench/apps/frappe/frappe/database/database.py", line 122, in sql
    self.connect()
  File "/home/ibrahim/frappe-bench/apps/frappe/frappe/database/database.py", line 75, in connect
    self._conn = self.get_connection()
  File "/home/ibrahim/frappe-bench/apps/frappe/frappe/database/mariadb/database.py", line 89, in get_connection
    conn = pymysql.connect(self.host, self.user or '', self.password or '',
  File "/home/ibrahim/frappe-bench/env/lib/python3.8/site-packages/pymysql/__init__.py", line 94, in Connect
    return Connection(*args, **kwargs)
  File "/home/ibrahim/frappe-bench/env/lib/python3.8/site-packages/pymysql/connections.py", line 325, in __init__
    self.connect()
  File "/home/ibrahim/frappe-bench/env/lib/python3.8/site-packages/pymysql/connections.py", line 630, in connect
    raise exc
pymysql.err.OperationalError: (2003, "Can't connect to MySQL server on 'library' ([Errno -3] Temporary failure in name resolution)")

2020-06-16 09:59:46,943 ERROR scheduler Exception in Enqueue Events for Site workie
Traceback (most recent call last):
  File "/home/ibrahim/frappe-bench/env/lib/python3.8/site-packages/pymysql/connections.py", line 581, in connect
    sock = socket.create_connection(
  File "/usr/lib/python3.8/socket.py", line 787, in create_connection
    for res in getaddrinfo(host, port, 0, SOCK_STREAM):
  File "/usr/lib/python3.8/socket.py", line 918, in getaddrinfo
    for res in _socket.getaddrinfo(host, port, family, type, proto, flags):
socket.gaierror: [Errno -3] Temporary failure in name resolution

During handling of the above exception, another exception occurred:

Traceback (most recent call last):
  File "/home/ibrahim/frappe-bench/apps/frappe/frappe/utils/scheduler.py", line 64, in enqueue_events_for_site
    if is_scheduler_inactive():
  File "/home/ibrahim/frappe-bench/apps/frappe/frappe/utils/scheduler.py", line 97, in is_scheduler_inactive
    if is_scheduler_disabled():
  File "/home/ibrahim/frappe-bench/apps/frappe/frappe/utils/scheduler.py", line 106, in is_scheduler_disabled
    return not frappe.utils.cint(frappe.db.get_single_value("System Settings", "enable_scheduler"))
  File "/home/ibrahim/frappe-bench/apps/frappe/frappe/database/database.py", line 559, in get_single_value
    val = self.sql("""select `value` from
  File "/home/ibrahim/frappe-bench/apps/frappe/frappe/database/database.py", line 122, in sql
    self.connect()
  File "/home/ibrahim/frappe-bench/apps/frappe/frappe/database/database.py", line 75, in connect
    self._conn = self.get_connection()
  File "/home/ibrahim/frappe-bench/apps/frappe/frappe/database/mariadb/database.py", line 89, in get_connection
    conn = pymysql.connect(self.host, self.user or '', self.password or '',
  File "/home/ibrahim/frappe-bench/env/lib/python3.8/site-packages/pymysql/__init__.py", line 94, in Connect
    return Connection(*args, **kwargs)
  File "/home/ibrahim/frappe-bench/env/lib/python3.8/site-packages/pymysql/connections.py", line 325, in __init__
    self.connect()
  File "/home/ibrahim/frappe-bench/env/lib/python3.8/site-packages/pymysql/connections.py", line 630, in connect
    raise exc
pymysql.err.OperationalError: (2003, "Can't connect to MySQL server on 'library' ([Errno -3] Temporary failure in name resolution)")

2020-06-16 10:00:47,302 ERROR scheduler Exception in Enqueue Events for Site VirtualOffice
Traceback (most recent call last):
  File "/home/ibrahim/frappe-bench/env/lib/python3.8/site-packages/pymysql/connections.py", line 581, in connect
    sock = socket.create_connection(
  File "/usr/lib/python3.8/socket.py", line 787, in create_connection
    for res in getaddrinfo(host, port, 0, SOCK_STREAM):
  File "/usr/lib/python3.8/socket.py", line 918, in getaddrinfo
    for res in _socket.getaddrinfo(host, port, family, type, proto, flags):
socket.gaierror: [Errno -3] Temporary failure in name resolution

During handling of the above exception, another exception occurred:

Traceback (most recent call last):
  File "/home/ibrahim/frappe-bench/apps/frappe/frappe/utils/scheduler.py", line 64, in enqueue_events_for_site
    if is_scheduler_inactive():
  File "/home/ibrahim/frappe-bench/apps/frappe/frappe/utils/scheduler.py", line 97, in is_scheduler_inactive
    if is_scheduler_disabled():
  File "/home/ibrahim/frappe-bench/apps/frappe/frappe/utils/scheduler.py", line 106, in is_scheduler_disabled
    return not frappe.utils.cint(frappe.db.get_single_value("System Settings", "enable_scheduler"))
  File "/home/ibrahim/frappe-bench/apps/frappe/frappe/database/database.py", line 559, in get_single_value
    val = self.sql("""select `value` from
  File "/home/ibrahim/frappe-bench/apps/frappe/frappe/database/database.py", line 122, in sql
    self.connect()
  File "/home/ibrahim/frappe-bench/apps/frappe/frappe/database/database.py", line 75, in connect
    self._conn = self.get_connection()
  File "/home/ibrahim/frappe-bench/apps/frappe/frappe/database/mariadb/database.py", line 89, in get_connection
    conn = pymysql.connect(self.host, self.user or '', self.password or '',
  File "/home/ibrahim/frappe-bench/env/lib/python3.8/site-packages/pymysql/__init__.py", line 94, in Connect
    return Connection(*args, **kwargs)
  File "/home/ibrahim/frappe-bench/env/lib/python3.8/site-packages/pymysql/connections.py", line 325, in __init__
    self.connect()
  File "/home/ibrahim/frappe-bench/env/lib/python3.8/site-packages/pymysql/connections.py", line 630, in connect
    raise exc
pymysql.err.OperationalError: (2003, "Can't connect to MySQL server on 'library' ([Errno -3] Temporary failure in name resolution)")

2020-06-16 10:00:47,308 ERROR scheduler Exception in Enqueue Events for Site library
Traceback (most recent call last):
  File "/home/ibrahim/frappe-bench/env/lib/python3.8/site-packages/pymysql/connections.py", line 581, in connect
    sock = socket.create_connection(
  File "/usr/lib/python3.8/socket.py", line 787, in create_connection
    for res in getaddrinfo(host, port, 0, SOCK_STREAM):
  File "/usr/lib/python3.8/socket.py", line 918, in getaddrinfo
    for res in _socket.getaddrinfo(host, port, family, type, proto, flags):
socket.gaierror: [Errno -3] Temporary failure in name resolution

During handling of the above exception, another exception occurred:

Traceback (most recent call last):
  File "/home/ibrahim/frappe-bench/apps/frappe/frappe/utils/scheduler.py", line 64, in enqueue_events_for_site
    if is_scheduler_inactive():
  File "/home/ibrahim/frappe-bench/apps/frappe/frappe/utils/scheduler.py", line 97, in is_scheduler_inactive
    if is_scheduler_disabled():
  File "/home/ibrahim/frappe-bench/apps/frappe/frappe/utils/scheduler.py", line 106, in is_scheduler_disabled
    return not frappe.utils.cint(frappe.db.get_single_value("System Settings", "enable_scheduler"))
  File "/home/ibrahim/frappe-bench/apps/frappe/frappe/database/database.py", line 559, in get_single_value
    val = self.sql("""select `value` from
  File "/home/ibrahim/frappe-bench/apps/frappe/frappe/database/database.py", line 122, in sql
    self.connect()
  File "/home/ibrahim/frappe-bench/apps/frappe/frappe/database/database.py", line 75, in connect
    self._conn = self.get_connection()
  File "/home/ibrahim/frappe-bench/apps/frappe/frappe/database/mariadb/database.py", line 89, in get_connection
    conn = pymysql.connect(self.host, self.user or '', self.password or '',
  File "/home/ibrahim/frappe-bench/env/lib/python3.8/site-packages/pymysql/__init__.py", line 94, in Connect
    return Connection(*args, **kwargs)
  File "/home/ibrahim/frappe-bench/env/lib/python3.8/site-packages/pymysql/connections.py", line 325, in __init__
    self.connect()
  File "/home/ibrahim/frappe-bench/env/lib/python3.8/site-packages/pymysql/connections.py", line 630, in connect
    raise exc
pymysql.err.OperationalError: (2003, "Can't connect to MySQL server on 'library' ([Errno -3] Temporary failure in name resolution)")

2020-06-16 10:00:47,312 ERROR scheduler Exception in Enqueue Events for Site workie
Traceback (most recent call last):
  File "/home/ibrahim/frappe-bench/env/lib/python3.8/site-packages/pymysql/connections.py", line 581, in connect
    sock = socket.create_connection(
  File "/usr/lib/python3.8/socket.py", line 787, in create_connection
    for res in getaddrinfo(host, port, 0, SOCK_STREAM):
  File "/usr/lib/python3.8/socket.py", line 918, in getaddrinfo
    for res in _socket.getaddrinfo(host, port, family, type, proto, flags):
socket.gaierror: [Errno -3] Temporary failure in name resolution

During handling of the above exception, another exception occurred:

Traceback (most recent call last):
  File "/home/ibrahim/frappe-bench/apps/frappe/frappe/utils/scheduler.py", line 64, in enqueue_events_for_site
    if is_scheduler_inactive():
  File "/home/ibrahim/frappe-bench/apps/frappe/frappe/utils/scheduler.py", line 97, in is_scheduler_inactive
    if is_scheduler_disabled():
  File "/home/ibrahim/frappe-bench/apps/frappe/frappe/utils/scheduler.py", line 106, in is_scheduler_disabled
    return not frappe.utils.cint(frappe.db.get_single_value("System Settings", "enable_scheduler"))
  File "/home/ibrahim/frappe-bench/apps/frappe/frappe/database/database.py", line 559, in get_single_value
    val = self.sql("""select `value` from
  File "/home/ibrahim/frappe-bench/apps/frappe/frappe/database/database.py", line 122, in sql
    self.connect()
  File "/home/ibrahim/frappe-bench/apps/frappe/frappe/database/database.py", line 75, in connect
    self._conn = self.get_connection()
  File "/home/ibrahim/frappe-bench/apps/frappe/frappe/database/mariadb/database.py", line 89, in get_connection
    conn = pymysql.connect(self.host, self.user or '', self.password or '',
  File "/home/ibrahim/frappe-bench/env/lib/python3.8/site-packages/pymysql/__init__.py", line 94, in Connect
    return Connection(*args, **kwargs)
  File "/home/ibrahim/frappe-bench/env/lib/python3.8/site-packages/pymysql/connections.py", line 325, in __init__
    self.connect()
  File "/home/ibrahim/frappe-bench/env/lib/python3.8/site-packages/pymysql/connections.py", line 630, in connect
    raise exc
pymysql.err.OperationalError: (2003, "Can't connect to MySQL server on 'library' ([Errno -3] Temporary failure in name resolution)")

2020-06-16 10:01:47,379 ERROR scheduler Exception in Enqueue Events for Site VirtualOffice
Traceback (most recent call last):
  File "/home/ibrahim/frappe-bench/env/lib/python3.8/site-packages/pymysql/connections.py", line 581, in connect
    sock = socket.create_connection(
  File "/usr/lib/python3.8/socket.py", line 787, in create_connection
    for res in getaddrinfo(host, port, 0, SOCK_STREAM):
  File "/usr/lib/python3.8/socket.py", line 918, in getaddrinfo
    for res in _socket.getaddrinfo(host, port, family, type, proto, flags):
socket.gaierror: [Errno -3] Temporary failure in name resolution

During handling of the above exception, another exception occurred:

Traceback (most recent call last):
  File "/home/ibrahim/frappe-bench/apps/frappe/frappe/utils/scheduler.py", line 64, in enqueue_events_for_site
    if is_scheduler_inactive():
  File "/home/ibrahim/frappe-bench/apps/frappe/frappe/utils/scheduler.py", line 97, in is_scheduler_inactive
    if is_scheduler_disabled():
  File "/home/ibrahim/frappe-bench/apps/frappe/frappe/utils/scheduler.py", line 106, in is_scheduler_disabled
    return not frappe.utils.cint(frappe.db.get_single_value("System Settings", "enable_scheduler"))
  File "/home/ibrahim/frappe-bench/apps/frappe/frappe/database/database.py", line 559, in get_single_value
    val = self.sql("""select `value` from
  File "/home/ibrahim/frappe-bench/apps/frappe/frappe/database/database.py", line 122, in sql
    self.connect()
  File "/home/ibrahim/frappe-bench/apps/frappe/frappe/database/database.py", line 75, in connect
    self._conn = self.get_connection()
  File "/home/ibrahim/frappe-bench/apps/frappe/frappe/database/mariadb/database.py", line 89, in get_connection
    conn = pymysql.connect(self.host, self.user or '', self.password or '',
  File "/home/ibrahim/frappe-bench/env/lib/python3.8/site-packages/pymysql/__init__.py", line 94, in Connect
    return Connection(*args, **kwargs)
  File "/home/ibrahim/frappe-bench/env/lib/python3.8/site-packages/pymysql/connections.py", line 325, in __init__
    self.connect()
  File "/home/ibrahim/frappe-bench/env/lib/python3.8/site-packages/pymysql/connections.py", line 630, in connect
    raise exc
pymysql.err.OperationalError: (2003, "Can't connect to MySQL server on 'library' ([Errno -3] Temporary failure in name resolution)")

2020-06-16 10:01:47,382 ERROR scheduler Exception in Enqueue Events for Site library
Traceback (most recent call last):
  File "/home/ibrahim/frappe-bench/env/lib/python3.8/site-packages/pymysql/connections.py", line 581, in connect
    sock = socket.create_connection(
  File "/usr/lib/python3.8/socket.py", line 787, in create_connection
    for res in getaddrinfo(host, port, 0, SOCK_STREAM):
  File "/usr/lib/python3.8/socket.py", line 918, in getaddrinfo
    for res in _socket.getaddrinfo(host, port, family, type, proto, flags):
socket.gaierror: [Errno -3] Temporary failure in name resolution

During handling of the above exception, another exception occurred:

Traceback (most recent call last):
  File "/home/ibrahim/frappe-bench/apps/frappe/frappe/utils/scheduler.py", line 64, in enqueue_events_for_site
    if is_scheduler_inactive():
  File "/home/ibrahim/frappe-bench/apps/frappe/frappe/utils/scheduler.py", line 97, in is_scheduler_inactive
    if is_scheduler_disabled():
  File "/home/ibrahim/frappe-bench/apps/frappe/frappe/utils/scheduler.py", line 106, in is_scheduler_disabled
    return not frappe.utils.cint(frappe.db.get_single_value("System Settings", "enable_scheduler"))
  File "/home/ibrahim/frappe-bench/apps/frappe/frappe/database/database.py", line 559, in get_single_value
    val = self.sql("""select `value` from
  File "/home/ibrahim/frappe-bench/apps/frappe/frappe/database/database.py", line 122, in sql
    self.connect()
  File "/home/ibrahim/frappe-bench/apps/frappe/frappe/database/database.py", line 75, in connect
    self._conn = self.get_connection()
  File "/home/ibrahim/frappe-bench/apps/frappe/frappe/database/mariadb/database.py", line 89, in get_connection
    conn = pymysql.connect(self.host, self.user or '', self.password or '',
  File "/home/ibrahim/frappe-bench/env/lib/python3.8/site-packages/pymysql/__init__.py", line 94, in Connect
    return Connection(*args, **kwargs)
  File "/home/ibrahim/frappe-bench/env/lib/python3.8/site-packages/pymysql/connections.py", line 325, in __init__
    self.connect()
  File "/home/ibrahim/frappe-bench/env/lib/python3.8/site-packages/pymysql/connections.py", line 630, in connect
    raise exc
pymysql.err.OperationalError: (2003, "Can't connect to MySQL server on 'library' ([Errno -3] Temporary failure in name resolution)")

2020-06-16 10:01:47,385 ERROR scheduler Exception in Enqueue Events for Site workie
Traceback (most recent call last):
  File "/home/ibrahim/frappe-bench/env/lib/python3.8/site-packages/pymysql/connections.py", line 581, in connect
    sock = socket.create_connection(
  File "/usr/lib/python3.8/socket.py", line 787, in create_connection
    for res in getaddrinfo(host, port, 0, SOCK_STREAM):
  File "/usr/lib/python3.8/socket.py", line 918, in getaddrinfo
    for res in _socket.getaddrinfo(host, port, family, type, proto, flags):
socket.gaierror: [Errno -3] Temporary failure in name resolution

During handling of the above exception, another exception occurred:

Traceback (most recent call last):
  File "/home/ibrahim/frappe-bench/apps/frappe/frappe/utils/scheduler.py", line 64, in enqueue_events_for_site
    if is_scheduler_inactive():
  File "/home/ibrahim/frappe-bench/apps/frappe/frappe/utils/scheduler.py", line 97, in is_scheduler_inactive
    if is_scheduler_disabled():
  File "/home/ibrahim/frappe-bench/apps/frappe/frappe/utils/scheduler.py", line 106, in is_scheduler_disabled
    return not frappe.utils.cint(frappe.db.get_single_value("System Settings", "enable_scheduler"))
  File "/home/ibrahim/frappe-bench/apps/frappe/frappe/database/database.py", line 559, in get_single_value
    val = self.sql("""select `value` from
  File "/home/ibrahim/frappe-bench/apps/frappe/frappe/database/database.py", line 122, in sql
    self.connect()
  File "/home/ibrahim/frappe-bench/apps/frappe/frappe/database/database.py", line 75, in connect
    self._conn = self.get_connection()
  File "/home/ibrahim/frappe-bench/apps/frappe/frappe/database/mariadb/database.py", line 89, in get_connection
    conn = pymysql.connect(self.host, self.user or '', self.password or '',
  File "/home/ibrahim/frappe-bench/env/lib/python3.8/site-packages/pymysql/__init__.py", line 94, in Connect
    return Connection(*args, **kwargs)
  File "/home/ibrahim/frappe-bench/env/lib/python3.8/site-packages/pymysql/connections.py", line 325, in __init__
    self.connect()
  File "/home/ibrahim/frappe-bench/env/lib/python3.8/site-packages/pymysql/connections.py", line 630, in connect
    raise exc
pymysql.err.OperationalError: (2003, "Can't connect to MySQL server on 'library' ([Errno -3] Temporary failure in name resolution)")

2020-06-16 10:02:47,454 ERROR scheduler Exception in Enqueue Events for Site VirtualOffice
Traceback (most recent call last):
  File "/home/ibrahim/frappe-bench/env/lib/python3.8/site-packages/pymysql/connections.py", line 581, in connect
    sock = socket.create_connection(
  File "/usr/lib/python3.8/socket.py", line 787, in create_connection
    for res in getaddrinfo(host, port, 0, SOCK_STREAM):
  File "/usr/lib/python3.8/socket.py", line 918, in getaddrinfo
    for res in _socket.getaddrinfo(host, port, family, type, proto, flags):
socket.gaierror: [Errno -3] Temporary failure in name resolution

During handling of the above exception, another exception occurred:

Traceback (most recent call last):
  File "/home/ibrahim/frappe-bench/apps/frappe/frappe/utils/scheduler.py", line 64, in enqueue_events_for_site
    if is_scheduler_inactive():
  File "/home/ibrahim/frappe-bench/apps/frappe/frappe/utils/scheduler.py", line 97, in is_scheduler_inactive
    if is_scheduler_disabled():
  File "/home/ibrahim/frappe-bench/apps/frappe/frappe/utils/scheduler.py", line 106, in is_scheduler_disabled
    return not frappe.utils.cint(frappe.db.get_single_value("System Settings", "enable_scheduler"))
  File "/home/ibrahim/frappe-bench/apps/frappe/frappe/database/database.py", line 559, in get_single_value
    val = self.sql("""select `value` from
  File "/home/ibrahim/frappe-bench/apps/frappe/frappe/database/database.py", line 122, in sql
    self.connect()
  File "/home/ibrahim/frappe-bench/apps/frappe/frappe/database/database.py", line 75, in connect
    self._conn = self.get_connection()
  File "/home/ibrahim/frappe-bench/apps/frappe/frappe/database/mariadb/database.py", line 89, in get_connection
    conn = pymysql.connect(self.host, self.user or '', self.password or '',
  File "/home/ibrahim/frappe-bench/env/lib/python3.8/site-packages/pymysql/__init__.py", line 94, in Connect
    return Connection(*args, **kwargs)
  File "/home/ibrahim/frappe-bench/env/lib/python3.8/site-packages/pymysql/connections.py", line 325, in __init__
    self.connect()
  File "/home/ibrahim/frappe-bench/env/lib/python3.8/site-packages/pymysql/connections.py", line 630, in connect
    raise exc
pymysql.err.OperationalError: (2003, "Can't connect to MySQL server on 'library' ([Errno -3] Temporary failure in name resolution)")

2020-06-16 10:02:47,458 ERROR scheduler Exception in Enqueue Events for Site library
Traceback (most recent call last):
  File "/home/ibrahim/frappe-bench/env/lib/python3.8/site-packages/pymysql/connections.py", line 581, in connect
    sock = socket.create_connection(
  File "/usr/lib/python3.8/socket.py", line 787, in create_connection
    for res in getaddrinfo(host, port, 0, SOCK_STREAM):
  File "/usr/lib/python3.8/socket.py", line 918, in getaddrinfo
    for res in _socket.getaddrinfo(host, port, family, type, proto, flags):
socket.gaierror: [Errno -3] Temporary failure in name resolution

During handling of the above exception, another exception occurred:

Traceback (most recent call last):
  File "/home/ibrahim/frappe-bench/apps/frappe/frappe/utils/scheduler.py", line 64, in enqueue_events_for_site
    if is_scheduler_inactive():
  File "/home/ibrahim/frappe-bench/apps/frappe/frappe/utils/scheduler.py", line 97, in is_scheduler_inactive
    if is_scheduler_disabled():
  File "/home/ibrahim/frappe-bench/apps/frappe/frappe/utils/scheduler.py", line 106, in is_scheduler_disabled
    return not frappe.utils.cint(frappe.db.get_single_value("System Settings", "enable_scheduler"))
  File "/home/ibrahim/frappe-bench/apps/frappe/frappe/database/database.py", line 559, in get_single_value
    val = self.sql("""select `value` from
  File "/home/ibrahim/frappe-bench/apps/frappe/frappe/database/database.py", line 122, in sql
    self.connect()
  File "/home/ibrahim/frappe-bench/apps/frappe/frappe/database/database.py", line 75, in connect
    self._conn = self.get_connection()
  File "/home/ibrahim/frappe-bench/apps/frappe/frappe/database/mariadb/database.py", line 89, in get_connection
    conn = pymysql.connect(self.host, self.user or '', self.password or '',
  File "/home/ibrahim/frappe-bench/env/lib/python3.8/site-packages/pymysql/__init__.py", line 94, in Connect
    return Connection(*args, **kwargs)
  File "/home/ibrahim/frappe-bench/env/lib/python3.8/site-packages/pymysql/connections.py", line 325, in __init__
    self.connect()
  File "/home/ibrahim/frappe-bench/env/lib/python3.8/site-packages/pymysql/connections.py", line 630, in connect
    raise exc
pymysql.err.OperationalError: (2003, "Can't connect to MySQL server on 'library' ([Errno -3] Temporary failure in name resolution)")

2020-06-16 10:02:47,459 ERROR scheduler Exception in Enqueue Events for Site workie
Traceback (most recent call last):
  File "/home/ibrahim/frappe-bench/env/lib/python3.8/site-packages/pymysql/connections.py", line 581, in connect
    sock = socket.create_connection(
  File "/usr/lib/python3.8/socket.py", line 787, in create_connection
    for res in getaddrinfo(host, port, 0, SOCK_STREAM):
  File "/usr/lib/python3.8/socket.py", line 918, in getaddrinfo
    for res in _socket.getaddrinfo(host, port, family, type, proto, flags):
socket.gaierror: [Errno -3] Temporary failure in name resolution

During handling of the above exception, another exception occurred:

Traceback (most recent call last):
  File "/home/ibrahim/frappe-bench/apps/frappe/frappe/utils/scheduler.py", line 64, in enqueue_events_for_site
    if is_scheduler_inactive():
  File "/home/ibrahim/frappe-bench/apps/frappe/frappe/utils/scheduler.py", line 97, in is_scheduler_inactive
    if is_scheduler_disabled():
  File "/home/ibrahim/frappe-bench/apps/frappe/frappe/utils/scheduler.py", line 106, in is_scheduler_disabled
    return not frappe.utils.cint(frappe.db.get_single_value("System Settings", "enable_scheduler"))
  File "/home/ibrahim/frappe-bench/apps/frappe/frappe/database/database.py", line 559, in get_single_value
    val = self.sql("""select `value` from
  File "/home/ibrahim/frappe-bench/apps/frappe/frappe/database/database.py", line 122, in sql
    self.connect()
  File "/home/ibrahim/frappe-bench/apps/frappe/frappe/database/database.py", line 75, in connect
    self._conn = self.get_connection()
  File "/home/ibrahim/frappe-bench/apps/frappe/frappe/database/mariadb/database.py", line 89, in get_connection
    conn = pymysql.connect(self.host, self.user or '', self.password or '',
  File "/home/ibrahim/frappe-bench/env/lib/python3.8/site-packages/pymysql/__init__.py", line 94, in Connect
    return Connection(*args, **kwargs)
  File "/home/ibrahim/frappe-bench/env/lib/python3.8/site-packages/pymysql/connections.py", line 325, in __init__
    self.connect()
  File "/home/ibrahim/frappe-bench/env/lib/python3.8/site-packages/pymysql/connections.py", line 630, in connect
    raise exc
pymysql.err.OperationalError: (2003, "Can't connect to MySQL server on 'library' ([Errno -3] Temporary failure in name resolution)")

2020-06-16 10:03:47,526 ERROR scheduler Exception in Enqueue Events for Site VirtualOffice
Traceback (most recent call last):
  File "/home/ibrahim/frappe-bench/env/lib/python3.8/site-packages/pymysql/connections.py", line 581, in connect
    sock = socket.create_connection(
  File "/usr/lib/python3.8/socket.py", line 787, in create_connection
    for res in getaddrinfo(host, port, 0, SOCK_STREAM):
  File "/usr/lib/python3.8/socket.py", line 918, in getaddrinfo
    for res in _socket.getaddrinfo(host, port, family, type, proto, flags):
socket.gaierror: [Errno -3] Temporary failure in name resolution

During handling of the above exception, another exception occurred:

Traceback (most recent call last):
  File "/home/ibrahim/frappe-bench/apps/frappe/frappe/utils/scheduler.py", line 64, in enqueue_events_for_site
    if is_scheduler_inactive():
  File "/home/ibrahim/frappe-bench/apps/frappe/frappe/utils/scheduler.py", line 97, in is_scheduler_inactive
    if is_scheduler_disabled():
  File "/home/ibrahim/frappe-bench/apps/frappe/frappe/utils/scheduler.py", line 106, in is_scheduler_disabled
    return not frappe.utils.cint(frappe.db.get_single_value("System Settings", "enable_scheduler"))
  File "/home/ibrahim/frappe-bench/apps/frappe/frappe/database/database.py", line 559, in get_single_value
    val = self.sql("""select `value` from
  File "/home/ibrahim/frappe-bench/apps/frappe/frappe/database/database.py", line 122, in sql
    self.connect()
  File "/home/ibrahim/frappe-bench/apps/frappe/frappe/database/database.py", line 75, in connect
    self._conn = self.get_connection()
  File "/home/ibrahim/frappe-bench/apps/frappe/frappe/database/mariadb/database.py", line 89, in get_connection
    conn = pymysql.connect(self.host, self.user or '', self.password or '',
  File "/home/ibrahim/frappe-bench/env/lib/python3.8/site-packages/pymysql/__init__.py", line 94, in Connect
    return Connection(*args, **kwargs)
  File "/home/ibrahim/frappe-bench/env/lib/python3.8/site-packages/pymysql/connections.py", line 325, in __init__
    self.connect()
  File "/home/ibrahim/frappe-bench/env/lib/python3.8/site-packages/pymysql/connections.py", line 630, in connect
    raise exc
pymysql.err.OperationalError: (2003, "Can't connect to MySQL server on 'library' ([Errno -3] Temporary failure in name resolution)")

2020-06-16 10:03:47,531 ERROR scheduler Exception in Enqueue Events for Site library
Traceback (most recent call last):
  File "/home/ibrahim/frappe-bench/env/lib/python3.8/site-packages/pymysql/connections.py", line 581, in connect
    sock = socket.create_connection(
  File "/usr/lib/python3.8/socket.py", line 787, in create_connection
    for res in getaddrinfo(host, port, 0, SOCK_STREAM):
  File "/usr/lib/python3.8/socket.py", line 918, in getaddrinfo
    for res in _socket.getaddrinfo(host, port, family, type, proto, flags):
socket.gaierror: [Errno -3] Temporary failure in name resolution

During handling of the above exception, another exception occurred:

Traceback (most recent call last):
  File "/home/ibrahim/frappe-bench/apps/frappe/frappe/utils/scheduler.py", line 64, in enqueue_events_for_site
    if is_scheduler_inactive():
  File "/home/ibrahim/frappe-bench/apps/frappe/frappe/utils/scheduler.py", line 97, in is_scheduler_inactive
    if is_scheduler_disabled():
  File "/home/ibrahim/frappe-bench/apps/frappe/frappe/utils/scheduler.py", line 106, in is_scheduler_disabled
    return not frappe.utils.cint(frappe.db.get_single_value("System Settings", "enable_scheduler"))
  File "/home/ibrahim/frappe-bench/apps/frappe/frappe/database/database.py", line 559, in get_single_value
    val = self.sql("""select `value` from
  File "/home/ibrahim/frappe-bench/apps/frappe/frappe/database/database.py", line 122, in sql
    self.connect()
  File "/home/ibrahim/frappe-bench/apps/frappe/frappe/database/database.py", line 75, in connect
    self._conn = self.get_connection()
  File "/home/ibrahim/frappe-bench/apps/frappe/frappe/database/mariadb/database.py", line 89, in get_connection
    conn = pymysql.connect(self.host, self.user or '', self.password or '',
  File "/home/ibrahim/frappe-bench/env/lib/python3.8/site-packages/pymysql/__init__.py", line 94, in Connect
    return Connection(*args, **kwargs)
  File "/home/ibrahim/frappe-bench/env/lib/python3.8/site-packages/pymysql/connections.py", line 325, in __init__
    self.connect()
  File "/home/ibrahim/frappe-bench/env/lib/python3.8/site-packages/pymysql/connections.py", line 630, in connect
    raise exc
pymysql.err.OperationalError: (2003, "Can't connect to MySQL server on 'library' ([Errno -3] Temporary failure in name resolution)")

2020-06-16 10:03:47,533 ERROR scheduler Exception in Enqueue Events for Site workie
Traceback (most recent call last):
  File "/home/ibrahim/frappe-bench/env/lib/python3.8/site-packages/pymysql/connections.py", line 581, in connect
    sock = socket.create_connection(
  File "/usr/lib/python3.8/socket.py", line 787, in create_connection
    for res in getaddrinfo(host, port, 0, SOCK_STREAM):
  File "/usr/lib/python3.8/socket.py", line 918, in getaddrinfo
    for res in _socket.getaddrinfo(host, port, family, type, proto, flags):
socket.gaierror: [Errno -3] Temporary failure in name resolution

During handling of the above exception, another exception occurred:

Traceback (most recent call last):
  File "/home/ibrahim/frappe-bench/apps/frappe/frappe/utils/scheduler.py", line 64, in enqueue_events_for_site
    if is_scheduler_inactive():
  File "/home/ibrahim/frappe-bench/apps/frappe/frappe/utils/scheduler.py", line 97, in is_scheduler_inactive
    if is_scheduler_disabled():
  File "/home/ibrahim/frappe-bench/apps/frappe/frappe/utils/scheduler.py", line 106, in is_scheduler_disabled
    return not frappe.utils.cint(frappe.db.get_single_value("System Settings", "enable_scheduler"))
  File "/home/ibrahim/frappe-bench/apps/frappe/frappe/database/database.py", line 559, in get_single_value
    val = self.sql("""select `value` from
  File "/home/ibrahim/frappe-bench/apps/frappe/frappe/database/database.py", line 122, in sql
    self.connect()
  File "/home/ibrahim/frappe-bench/apps/frappe/frappe/database/database.py", line 75, in connect
    self._conn = self.get_connection()
  File "/home/ibrahim/frappe-bench/apps/frappe/frappe/database/mariadb/database.py", line 89, in get_connection
    conn = pymysql.connect(self.host, self.user or '', self.password or '',
  File "/home/ibrahim/frappe-bench/env/lib/python3.8/site-packages/pymysql/__init__.py", line 94, in Connect
    return Connection(*args, **kwargs)
  File "/home/ibrahim/frappe-bench/env/lib/python3.8/site-packages/pymysql/connections.py", line 325, in __init__
    self.connect()
  File "/home/ibrahim/frappe-bench/env/lib/python3.8/site-packages/pymysql/connections.py", line 630, in connect
    raise exc
pymysql.err.OperationalError: (2003, "Can't connect to MySQL server on 'library' ([Errno -3] Temporary failure in name resolution)")

2020-06-16 14:15:59,260 ERROR scheduler Exception in Enqueue Events for Site VirtualOffice
Traceback (most recent call last):
  File "/home/ibrahim/frappe-bench/env/lib/python3.8/site-packages/pymysql/connections.py", line 581, in connect
    sock = socket.create_connection(
  File "/usr/lib/python3.8/socket.py", line 787, in create_connection
    for res in getaddrinfo(host, port, 0, SOCK_STREAM):
  File "/usr/lib/python3.8/socket.py", line 918, in getaddrinfo
    for res in _socket.getaddrinfo(host, port, family, type, proto, flags):
socket.gaierror: [Errno -3] Temporary failure in name resolution

During handling of the above exception, another exception occurred:

Traceback (most recent call last):
  File "/home/ibrahim/frappe-bench/apps/frappe/frappe/utils/scheduler.py", line 64, in enqueue_events_for_site
    if is_scheduler_inactive():
  File "/home/ibrahim/frappe-bench/apps/frappe/frappe/utils/scheduler.py", line 97, in is_scheduler_inactive
    if is_scheduler_disabled():
  File "/home/ibrahim/frappe-bench/apps/frappe/frappe/utils/scheduler.py", line 106, in is_scheduler_disabled
    return not frappe.utils.cint(frappe.db.get_single_value("System Settings", "enable_scheduler"))
  File "/home/ibrahim/frappe-bench/apps/frappe/frappe/database/database.py", line 559, in get_single_value
    val = self.sql("""select `value` from
  File "/home/ibrahim/frappe-bench/apps/frappe/frappe/database/database.py", line 122, in sql
    self.connect()
  File "/home/ibrahim/frappe-bench/apps/frappe/frappe/database/database.py", line 75, in connect
    self._conn = self.get_connection()
  File "/home/ibrahim/frappe-bench/apps/frappe/frappe/database/mariadb/database.py", line 89, in get_connection
    conn = pymysql.connect(self.host, self.user or '', self.password or '',
  File "/home/ibrahim/frappe-bench/env/lib/python3.8/site-packages/pymysql/__init__.py", line 94, in Connect
    return Connection(*args, **kwargs)
  File "/home/ibrahim/frappe-bench/env/lib/python3.8/site-packages/pymysql/connections.py", line 325, in __init__
    self.connect()
  File "/home/ibrahim/frappe-bench/env/lib/python3.8/site-packages/pymysql/connections.py", line 630, in connect
    raise exc
pymysql.err.OperationalError: (2003, "Can't connect to MySQL server on 'library' ([Errno -3] Temporary failure in name resolution)")

2020-06-16 14:15:59,801 ERROR scheduler Exception in Enqueue Events for Site library
Traceback (most recent call last):
  File "/home/ibrahim/frappe-bench/env/lib/python3.8/site-packages/pymysql/connections.py", line 581, in connect
    sock = socket.create_connection(
  File "/usr/lib/python3.8/socket.py", line 787, in create_connection
    for res in getaddrinfo(host, port, 0, SOCK_STREAM):
  File "/usr/lib/python3.8/socket.py", line 918, in getaddrinfo
    for res in _socket.getaddrinfo(host, port, family, type, proto, flags):
socket.gaierror: [Errno -3] Temporary failure in name resolution

During handling of the above exception, another exception occurred:

Traceback (most recent call last):
  File "/home/ibrahim/frappe-bench/apps/frappe/frappe/utils/scheduler.py", line 64, in enqueue_events_for_site
    if is_scheduler_inactive():
  File "/home/ibrahim/frappe-bench/apps/frappe/frappe/utils/scheduler.py", line 97, in is_scheduler_inactive
    if is_scheduler_disabled():
  File "/home/ibrahim/frappe-bench/apps/frappe/frappe/utils/scheduler.py", line 106, in is_scheduler_disabled
    return not frappe.utils.cint(frappe.db.get_single_value("System Settings", "enable_scheduler"))
  File "/home/ibrahim/frappe-bench/apps/frappe/frappe/database/database.py", line 559, in get_single_value
    val = self.sql("""select `value` from
  File "/home/ibrahim/frappe-bench/apps/frappe/frappe/database/database.py", line 122, in sql
    self.connect()
  File "/home/ibrahim/frappe-bench/apps/frappe/frappe/database/database.py", line 75, in connect
    self._conn = self.get_connection()
  File "/home/ibrahim/frappe-bench/apps/frappe/frappe/database/mariadb/database.py", line 89, in get_connection
    conn = pymysql.connect(self.host, self.user or '', self.password or '',
  File "/home/ibrahim/frappe-bench/env/lib/python3.8/site-packages/pymysql/__init__.py", line 94, in Connect
    return Connection(*args, **kwargs)
  File "/home/ibrahim/frappe-bench/env/lib/python3.8/site-packages/pymysql/connections.py", line 325, in __init__
    self.connect()
  File "/home/ibrahim/frappe-bench/env/lib/python3.8/site-packages/pymysql/connections.py", line 630, in connect
    raise exc
pymysql.err.OperationalError: (2003, "Can't connect to MySQL server on 'library' ([Errno -3] Temporary failure in name resolution)")

2020-06-16 14:16:00,085 ERROR scheduler Exception in Enqueue Events for Site workie
Traceback (most recent call last):
  File "/home/ibrahim/frappe-bench/env/lib/python3.8/site-packages/pymysql/connections.py", line 581, in connect
    sock = socket.create_connection(
  File "/usr/lib/python3.8/socket.py", line 787, in create_connection
    for res in getaddrinfo(host, port, 0, SOCK_STREAM):
  File "/usr/lib/python3.8/socket.py", line 918, in getaddrinfo
    for res in _socket.getaddrinfo(host, port, family, type, proto, flags):
socket.gaierror: [Errno -3] Temporary failure in name resolution

During handling of the above exception, another exception occurred:

Traceback (most recent call last):
  File "/home/ibrahim/frappe-bench/apps/frappe/frappe/utils/scheduler.py", line 64, in enqueue_events_for_site
    if is_scheduler_inactive():
  File "/home/ibrahim/frappe-bench/apps/frappe/frappe/utils/scheduler.py", line 97, in is_scheduler_inactive
    if is_scheduler_disabled():
  File "/home/ibrahim/frappe-bench/apps/frappe/frappe/utils/scheduler.py", line 106, in is_scheduler_disabled
    return not frappe.utils.cint(frappe.db.get_single_value("System Settings", "enable_scheduler"))
  File "/home/ibrahim/frappe-bench/apps/frappe/frappe/database/database.py", line 559, in get_single_value
    val = self.sql("""select `value` from
  File "/home/ibrahim/frappe-bench/apps/frappe/frappe/database/database.py", line 122, in sql
    self.connect()
  File "/home/ibrahim/frappe-bench/apps/frappe/frappe/database/database.py", line 75, in connect
    self._conn = self.get_connection()
  File "/home/ibrahim/frappe-bench/apps/frappe/frappe/database/mariadb/database.py", line 89, in get_connection
    conn = pymysql.connect(self.host, self.user or '', self.password or '',
  File "/home/ibrahim/frappe-bench/env/lib/python3.8/site-packages/pymysql/__init__.py", line 94, in Connect
    return Connection(*args, **kwargs)
  File "/home/ibrahim/frappe-bench/env/lib/python3.8/site-packages/pymysql/connections.py", line 325, in __init__
    self.connect()
  File "/home/ibrahim/frappe-bench/env/lib/python3.8/site-packages/pymysql/connections.py", line 630, in connect
    raise exc
pymysql.err.OperationalError: (2003, "Can't connect to MySQL server on 'library' ([Errno -3] Temporary failure in name resolution)")

2020-06-16 14:17:00,320 ERROR scheduler Exception in Enqueue Events for Site VirtualOffice
Traceback (most recent call last):
  File "/home/ibrahim/frappe-bench/env/lib/python3.8/site-packages/pymysql/connections.py", line 581, in connect
    sock = socket.create_connection(
  File "/usr/lib/python3.8/socket.py", line 787, in create_connection
    for res in getaddrinfo(host, port, 0, SOCK_STREAM):
  File "/usr/lib/python3.8/socket.py", line 918, in getaddrinfo
    for res in _socket.getaddrinfo(host, port, family, type, proto, flags):
socket.gaierror: [Errno -3] Temporary failure in name resolution

During handling of the above exception, another exception occurred:

Traceback (most recent call last):
  File "/home/ibrahim/frappe-bench/apps/frappe/frappe/utils/scheduler.py", line 64, in enqueue_events_for_site
    if is_scheduler_inactive():
  File "/home/ibrahim/frappe-bench/apps/frappe/frappe/utils/scheduler.py", line 97, in is_scheduler_inactive
    if is_scheduler_disabled():
  File "/home/ibrahim/frappe-bench/apps/frappe/frappe/utils/scheduler.py", line 106, in is_scheduler_disabled
    return not frappe.utils.cint(frappe.db.get_single_value("System Settings", "enable_scheduler"))
  File "/home/ibrahim/frappe-bench/apps/frappe/frappe/database/database.py", line 559, in get_single_value
    val = self.sql("""select `value` from
  File "/home/ibrahim/frappe-bench/apps/frappe/frappe/database/database.py", line 122, in sql
    self.connect()
  File "/home/ibrahim/frappe-bench/apps/frappe/frappe/database/database.py", line 75, in connect
    self._conn = self.get_connection()
  File "/home/ibrahim/frappe-bench/apps/frappe/frappe/database/mariadb/database.py", line 89, in get_connection
    conn = pymysql.connect(self.host, self.user or '', self.password or '',
  File "/home/ibrahim/frappe-bench/env/lib/python3.8/site-packages/pymysql/__init__.py", line 94, in Connect
    return Connection(*args, **kwargs)
  File "/home/ibrahim/frappe-bench/env/lib/python3.8/site-packages/pymysql/connections.py", line 325, in __init__
    self.connect()
  File "/home/ibrahim/frappe-bench/env/lib/python3.8/site-packages/pymysql/connections.py", line 630, in connect
    raise exc
pymysql.err.OperationalError: (2003, "Can't connect to MySQL server on 'library' ([Errno -3] Temporary failure in name resolution)")

2020-06-16 14:17:00,321 ERROR scheduler Exception in Enqueue Events for Site library
Traceback (most recent call last):
  File "/home/ibrahim/frappe-bench/env/lib/python3.8/site-packages/pymysql/connections.py", line 581, in connect
    sock = socket.create_connection(
  File "/usr/lib/python3.8/socket.py", line 787, in create_connection
    for res in getaddrinfo(host, port, 0, SOCK_STREAM):
  File "/usr/lib/python3.8/socket.py", line 918, in getaddrinfo
    for res in _socket.getaddrinfo(host, port, family, type, proto, flags):
socket.gaierror: [Errno -3] Temporary failure in name resolution

During handling of the above exception, another exception occurred:

Traceback (most recent call last):
  File "/home/ibrahim/frappe-bench/apps/frappe/frappe/utils/scheduler.py", line 64, in enqueue_events_for_site
    if is_scheduler_inactive():
  File "/home/ibrahim/frappe-bench/apps/frappe/frappe/utils/scheduler.py", line 97, in is_scheduler_inactive
    if is_scheduler_disabled():
  File "/home/ibrahim/frappe-bench/apps/frappe/frappe/utils/scheduler.py", line 106, in is_scheduler_disabled
    return not frappe.utils.cint(frappe.db.get_single_value("System Settings", "enable_scheduler"))
  File "/home/ibrahim/frappe-bench/apps/frappe/frappe/database/database.py", line 559, in get_single_value
    val = self.sql("""select `value` from
  File "/home/ibrahim/frappe-bench/apps/frappe/frappe/database/database.py", line 122, in sql
    self.connect()
  File "/home/ibrahim/frappe-bench/apps/frappe/frappe/database/database.py", line 75, in connect
    self._conn = self.get_connection()
  File "/home/ibrahim/frappe-bench/apps/frappe/frappe/database/mariadb/database.py", line 89, in get_connection
    conn = pymysql.connect(self.host, self.user or '', self.password or '',
  File "/home/ibrahim/frappe-bench/env/lib/python3.8/site-packages/pymysql/__init__.py", line 94, in Connect
    return Connection(*args, **kwargs)
  File "/home/ibrahim/frappe-bench/env/lib/python3.8/site-packages/pymysql/connections.py", line 325, in __init__
    self.connect()
  File "/home/ibrahim/frappe-bench/env/lib/python3.8/site-packages/pymysql/connections.py", line 630, in connect
    raise exc
pymysql.err.OperationalError: (2003, "Can't connect to MySQL server on 'library' ([Errno -3] Temporary failure in name resolution)")

2020-06-16 14:17:00,323 ERROR scheduler Exception in Enqueue Events for Site workie
Traceback (most recent call last):
  File "/home/ibrahim/frappe-bench/env/lib/python3.8/site-packages/pymysql/connections.py", line 581, in connect
    sock = socket.create_connection(
  File "/usr/lib/python3.8/socket.py", line 787, in create_connection
    for res in getaddrinfo(host, port, 0, SOCK_STREAM):
  File "/usr/lib/python3.8/socket.py", line 918, in getaddrinfo
    for res in _socket.getaddrinfo(host, port, family, type, proto, flags):
socket.gaierror: [Errno -3] Temporary failure in name resolution

During handling of the above exception, another exception occurred:

Traceback (most recent call last):
  File "/home/ibrahim/frappe-bench/apps/frappe/frappe/utils/scheduler.py", line 64, in enqueue_events_for_site
    if is_scheduler_inactive():
  File "/home/ibrahim/frappe-bench/apps/frappe/frappe/utils/scheduler.py", line 97, in is_scheduler_inactive
    if is_scheduler_disabled():
  File "/home/ibrahim/frappe-bench/apps/frappe/frappe/utils/scheduler.py", line 106, in is_scheduler_disabled
    return not frappe.utils.cint(frappe.db.get_single_value("System Settings", "enable_scheduler"))
  File "/home/ibrahim/frappe-bench/apps/frappe/frappe/database/database.py", line 559, in get_single_value
    val = self.sql("""select `value` from
  File "/home/ibrahim/frappe-bench/apps/frappe/frappe/database/database.py", line 122, in sql
    self.connect()
  File "/home/ibrahim/frappe-bench/apps/frappe/frappe/database/database.py", line 75, in connect
    self._conn = self.get_connection()
  File "/home/ibrahim/frappe-bench/apps/frappe/frappe/database/mariadb/database.py", line 89, in get_connection
    conn = pymysql.connect(self.host, self.user or '', self.password or '',
  File "/home/ibrahim/frappe-bench/env/lib/python3.8/site-packages/pymysql/__init__.py", line 94, in Connect
    return Connection(*args, **kwargs)
  File "/home/ibrahim/frappe-bench/env/lib/python3.8/site-packages/pymysql/connections.py", line 325, in __init__
    self.connect()
  File "/home/ibrahim/frappe-bench/env/lib/python3.8/site-packages/pymysql/connections.py", line 630, in connect
    raise exc
pymysql.err.OperationalError: (2003, "Can't connect to MySQL server on 'library' ([Errno -3] Temporary failure in name resolution)")

2020-06-16 14:18:00,862 ERROR scheduler Exception in Enqueue Events for Site VirtualOffice
Traceback (most recent call last):
  File "/home/ibrahim/frappe-bench/env/lib/python3.8/site-packages/pymysql/connections.py", line 581, in connect
    sock = socket.create_connection(
  File "/usr/lib/python3.8/socket.py", line 787, in create_connection
    for res in getaddrinfo(host, port, 0, SOCK_STREAM):
  File "/usr/lib/python3.8/socket.py", line 918, in getaddrinfo
    for res in _socket.getaddrinfo(host, port, family, type, proto, flags):
socket.gaierror: [Errno -3] Temporary failure in name resolution

During handling of the above exception, another exception occurred:

Traceback (most recent call last):
  File "/home/ibrahim/frappe-bench/apps/frappe/frappe/utils/scheduler.py", line 64, in enqueue_events_for_site
    if is_scheduler_inactive():
  File "/home/ibrahim/frappe-bench/apps/frappe/frappe/utils/scheduler.py", line 97, in is_scheduler_inactive
    if is_scheduler_disabled():
  File "/home/ibrahim/frappe-bench/apps/frappe/frappe/utils/scheduler.py", line 106, in is_scheduler_disabled
    return not frappe.utils.cint(frappe.db.get_single_value("System Settings", "enable_scheduler"))
  File "/home/ibrahim/frappe-bench/apps/frappe/frappe/database/database.py", line 559, in get_single_value
    val = self.sql("""select `value` from
  File "/home/ibrahim/frappe-bench/apps/frappe/frappe/database/database.py", line 122, in sql
    self.connect()
  File "/home/ibrahim/frappe-bench/apps/frappe/frappe/database/database.py", line 75, in connect
    self._conn = self.get_connection()
  File "/home/ibrahim/frappe-bench/apps/frappe/frappe/database/mariadb/database.py", line 89, in get_connection
    conn = pymysql.connect(self.host, self.user or '', self.password or '',
  File "/home/ibrahim/frappe-bench/env/lib/python3.8/site-packages/pymysql/__init__.py", line 94, in Connect
    return Connection(*args, **kwargs)
  File "/home/ibrahim/frappe-bench/env/lib/python3.8/site-packages/pymysql/connections.py", line 325, in __init__
    self.connect()
  File "/home/ibrahim/frappe-bench/env/lib/python3.8/site-packages/pymysql/connections.py", line 630, in connect
    raise exc
pymysql.err.OperationalError: (2003, "Can't connect to MySQL server on 'library' ([Errno -3] Temporary failure in name resolution)")

2020-06-16 14:18:02,049 ERROR scheduler Exception in Enqueue Events for Site library
Traceback (most recent call last):
  File "/home/ibrahim/frappe-bench/env/lib/python3.8/site-packages/pymysql/connections.py", line 581, in connect
    sock = socket.create_connection(
  File "/usr/lib/python3.8/socket.py", line 787, in create_connection
    for res in getaddrinfo(host, port, 0, SOCK_STREAM):
  File "/usr/lib/python3.8/socket.py", line 918, in getaddrinfo
    for res in _socket.getaddrinfo(host, port, family, type, proto, flags):
socket.gaierror: [Errno -3] Temporary failure in name resolution

During handling of the above exception, another exception occurred:

Traceback (most recent call last):
  File "/home/ibrahim/frappe-bench/apps/frappe/frappe/utils/scheduler.py", line 64, in enqueue_events_for_site
    if is_scheduler_inactive():
  File "/home/ibrahim/frappe-bench/apps/frappe/frappe/utils/scheduler.py", line 97, in is_scheduler_inactive
    if is_scheduler_disabled():
  File "/home/ibrahim/frappe-bench/apps/frappe/frappe/utils/scheduler.py", line 106, in is_scheduler_disabled
    return not frappe.utils.cint(frappe.db.get_single_value("System Settings", "enable_scheduler"))
  File "/home/ibrahim/frappe-bench/apps/frappe/frappe/database/database.py", line 559, in get_single_value
    val = self.sql("""select `value` from
  File "/home/ibrahim/frappe-bench/apps/frappe/frappe/database/database.py", line 122, in sql
    self.connect()
  File "/home/ibrahim/frappe-bench/apps/frappe/frappe/database/database.py", line 75, in connect
    self._conn = self.get_connection()
  File "/home/ibrahim/frappe-bench/apps/frappe/frappe/database/mariadb/database.py", line 89, in get_connection
    conn = pymysql.connect(self.host, self.user or '', self.password or '',
  File "/home/ibrahim/frappe-bench/env/lib/python3.8/site-packages/pymysql/__init__.py", line 94, in Connect
    return Connection(*args, **kwargs)
  File "/home/ibrahim/frappe-bench/env/lib/python3.8/site-packages/pymysql/connections.py", line 325, in __init__
    self.connect()
  File "/home/ibrahim/frappe-bench/env/lib/python3.8/site-packages/pymysql/connections.py", line 630, in connect
    raise exc
pymysql.err.OperationalError: (2003, "Can't connect to MySQL server on 'library' ([Errno -3] Temporary failure in name resolution)")

2020-06-16 14:18:02,119 ERROR scheduler Exception in Enqueue Events for Site workie
Traceback (most recent call last):
  File "/home/ibrahim/frappe-bench/env/lib/python3.8/site-packages/pymysql/connections.py", line 581, in connect
    sock = socket.create_connection(
  File "/usr/lib/python3.8/socket.py", line 787, in create_connection
    for res in getaddrinfo(host, port, 0, SOCK_STREAM):
  File "/usr/lib/python3.8/socket.py", line 918, in getaddrinfo
    for res in _socket.getaddrinfo(host, port, family, type, proto, flags):
socket.gaierror: [Errno -3] Temporary failure in name resolution

During handling of the above exception, another exception occurred:

Traceback (most recent call last):
  File "/home/ibrahim/frappe-bench/apps/frappe/frappe/utils/scheduler.py", line 64, in enqueue_events_for_site
    if is_scheduler_inactive():
  File "/home/ibrahim/frappe-bench/apps/frappe/frappe/utils/scheduler.py", line 97, in is_scheduler_inactive
    if is_scheduler_disabled():
  File "/home/ibrahim/frappe-bench/apps/frappe/frappe/utils/scheduler.py", line 106, in is_scheduler_disabled
    return not frappe.utils.cint(frappe.db.get_single_value("System Settings", "enable_scheduler"))
  File "/home/ibrahim/frappe-bench/apps/frappe/frappe/database/database.py", line 559, in get_single_value
    val = self.sql("""select `value` from
  File "/home/ibrahim/frappe-bench/apps/frappe/frappe/database/database.py", line 122, in sql
    self.connect()
  File "/home/ibrahim/frappe-bench/apps/frappe/frappe/database/database.py", line 75, in connect
    self._conn = self.get_connection()
  File "/home/ibrahim/frappe-bench/apps/frappe/frappe/database/mariadb/database.py", line 89, in get_connection
    conn = pymysql.connect(self.host, self.user or '', self.password or '',
  File "/home/ibrahim/frappe-bench/env/lib/python3.8/site-packages/pymysql/__init__.py", line 94, in Connect
    return Connection(*args, **kwargs)
  File "/home/ibrahim/frappe-bench/env/lib/python3.8/site-packages/pymysql/connections.py", line 325, in __init__
    self.connect()
  File "/home/ibrahim/frappe-bench/env/lib/python3.8/site-packages/pymysql/connections.py", line 630, in connect
    raise exc
pymysql.err.OperationalError: (2003, "Can't connect to MySQL server on 'library' ([Errno -3] Temporary failure in name resolution)")

2020-06-16 17:02:41,083 ERROR scheduler Exception in Enqueue Events for Site VirtualOffice
Traceback (most recent call last):
  File "/home/ibrahim/frappe-bench/env/lib/python3.8/site-packages/pymysql/connections.py", line 581, in connect
    sock = socket.create_connection(
  File "/usr/lib/python3.8/socket.py", line 787, in create_connection
    for res in getaddrinfo(host, port, 0, SOCK_STREAM):
  File "/usr/lib/python3.8/socket.py", line 918, in getaddrinfo
    for res in _socket.getaddrinfo(host, port, family, type, proto, flags):
socket.gaierror: [Errno -3] Temporary failure in name resolution

During handling of the above exception, another exception occurred:

Traceback (most recent call last):
  File "/home/ibrahim/frappe-bench/apps/frappe/frappe/utils/scheduler.py", line 64, in enqueue_events_for_site
    if is_scheduler_inactive():
  File "/home/ibrahim/frappe-bench/apps/frappe/frappe/utils/scheduler.py", line 97, in is_scheduler_inactive
    if is_scheduler_disabled():
  File "/home/ibrahim/frappe-bench/apps/frappe/frappe/utils/scheduler.py", line 106, in is_scheduler_disabled
    return not frappe.utils.cint(frappe.db.get_single_value("System Settings", "enable_scheduler"))
  File "/home/ibrahim/frappe-bench/apps/frappe/frappe/database/database.py", line 559, in get_single_value
    val = self.sql("""select `value` from
  File "/home/ibrahim/frappe-bench/apps/frappe/frappe/database/database.py", line 122, in sql
    self.connect()
  File "/home/ibrahim/frappe-bench/apps/frappe/frappe/database/database.py", line 75, in connect
    self._conn = self.get_connection()
  File "/home/ibrahim/frappe-bench/apps/frappe/frappe/database/mariadb/database.py", line 89, in get_connection
    conn = pymysql.connect(self.host, self.user or '', self.password or '',
  File "/home/ibrahim/frappe-bench/env/lib/python3.8/site-packages/pymysql/__init__.py", line 94, in Connect
    return Connection(*args, **kwargs)
  File "/home/ibrahim/frappe-bench/env/lib/python3.8/site-packages/pymysql/connections.py", line 325, in __init__
    self.connect()
  File "/home/ibrahim/frappe-bench/env/lib/python3.8/site-packages/pymysql/connections.py", line 630, in connect
    raise exc
pymysql.err.OperationalError: (2003, "Can't connect to MySQL server on 'library' ([Errno -3] Temporary failure in name resolution)")

2020-06-16 17:02:41,473 ERROR scheduler Exception in Enqueue Events for Site library
Traceback (most recent call last):
  File "/home/ibrahim/frappe-bench/env/lib/python3.8/site-packages/pymysql/connections.py", line 581, in connect
    sock = socket.create_connection(
  File "/usr/lib/python3.8/socket.py", line 787, in create_connection
    for res in getaddrinfo(host, port, 0, SOCK_STREAM):
  File "/usr/lib/python3.8/socket.py", line 918, in getaddrinfo
    for res in _socket.getaddrinfo(host, port, family, type, proto, flags):
socket.gaierror: [Errno -3] Temporary failure in name resolution

During handling of the above exception, another exception occurred:

Traceback (most recent call last):
  File "/home/ibrahim/frappe-bench/apps/frappe/frappe/utils/scheduler.py", line 64, in enqueue_events_for_site
    if is_scheduler_inactive():
  File "/home/ibrahim/frappe-bench/apps/frappe/frappe/utils/scheduler.py", line 97, in is_scheduler_inactive
    if is_scheduler_disabled():
  File "/home/ibrahim/frappe-bench/apps/frappe/frappe/utils/scheduler.py", line 106, in is_scheduler_disabled
    return not frappe.utils.cint(frappe.db.get_single_value("System Settings", "enable_scheduler"))
  File "/home/ibrahim/frappe-bench/apps/frappe/frappe/database/database.py", line 559, in get_single_value
    val = self.sql("""select `value` from
  File "/home/ibrahim/frappe-bench/apps/frappe/frappe/database/database.py", line 122, in sql
    self.connect()
  File "/home/ibrahim/frappe-bench/apps/frappe/frappe/database/database.py", line 75, in connect
    self._conn = self.get_connection()
  File "/home/ibrahim/frappe-bench/apps/frappe/frappe/database/mariadb/database.py", line 89, in get_connection
    conn = pymysql.connect(self.host, self.user or '', self.password or '',
  File "/home/ibrahim/frappe-bench/env/lib/python3.8/site-packages/pymysql/__init__.py", line 94, in Connect
    return Connection(*args, **kwargs)
  File "/home/ibrahim/frappe-bench/env/lib/python3.8/site-packages/pymysql/connections.py", line 325, in __init__
    self.connect()
  File "/home/ibrahim/frappe-bench/env/lib/python3.8/site-packages/pymysql/connections.py", line 630, in connect
    raise exc
pymysql.err.OperationalError: (2003, "Can't connect to MySQL server on 'library' ([Errno -3] Temporary failure in name resolution)")

2020-06-16 17:02:41,574 ERROR scheduler Exception in Enqueue Events for Site workie
Traceback (most recent call last):
  File "/home/ibrahim/frappe-bench/env/lib/python3.8/site-packages/pymysql/connections.py", line 581, in connect
    sock = socket.create_connection(
  File "/usr/lib/python3.8/socket.py", line 787, in create_connection
    for res in getaddrinfo(host, port, 0, SOCK_STREAM):
  File "/usr/lib/python3.8/socket.py", line 918, in getaddrinfo
    for res in _socket.getaddrinfo(host, port, family, type, proto, flags):
socket.gaierror: [Errno -3] Temporary failure in name resolution

During handling of the above exception, another exception occurred:

Traceback (most recent call last):
  File "/home/ibrahim/frappe-bench/apps/frappe/frappe/utils/scheduler.py", line 64, in enqueue_events_for_site
    if is_scheduler_inactive():
  File "/home/ibrahim/frappe-bench/apps/frappe/frappe/utils/scheduler.py", line 97, in is_scheduler_inactive
    if is_scheduler_disabled():
  File "/home/ibrahim/frappe-bench/apps/frappe/frappe/utils/scheduler.py", line 106, in is_scheduler_disabled
    return not frappe.utils.cint(frappe.db.get_single_value("System Settings", "enable_scheduler"))
  File "/home/ibrahim/frappe-bench/apps/frappe/frappe/database/database.py", line 559, in get_single_value
    val = self.sql("""select `value` from
  File "/home/ibrahim/frappe-bench/apps/frappe/frappe/database/database.py", line 122, in sql
    self.connect()
  File "/home/ibrahim/frappe-bench/apps/frappe/frappe/database/database.py", line 75, in connect
    self._conn = self.get_connection()
  File "/home/ibrahim/frappe-bench/apps/frappe/frappe/database/mariadb/database.py", line 89, in get_connection
    conn = pymysql.connect(self.host, self.user or '', self.password or '',
  File "/home/ibrahim/frappe-bench/env/lib/python3.8/site-packages/pymysql/__init__.py", line 94, in Connect
    return Connection(*args, **kwargs)
  File "/home/ibrahim/frappe-bench/env/lib/python3.8/site-packages/pymysql/connections.py", line 325, in __init__
    self.connect()
  File "/home/ibrahim/frappe-bench/env/lib/python3.8/site-packages/pymysql/connections.py", line 630, in connect
    raise exc
pymysql.err.OperationalError: (2003, "Can't connect to MySQL server on 'library' ([Errno -3] Temporary failure in name resolution)")

2020-06-16 17:03:41,950 ERROR scheduler Exception in Enqueue Events for Site VirtualOffice
Traceback (most recent call last):
  File "/home/ibrahim/frappe-bench/env/lib/python3.8/site-packages/pymysql/connections.py", line 581, in connect
    sock = socket.create_connection(
  File "/usr/lib/python3.8/socket.py", line 787, in create_connection
    for res in getaddrinfo(host, port, 0, SOCK_STREAM):
  File "/usr/lib/python3.8/socket.py", line 918, in getaddrinfo
    for res in _socket.getaddrinfo(host, port, family, type, proto, flags):
socket.gaierror: [Errno -3] Temporary failure in name resolution

During handling of the above exception, another exception occurred:

Traceback (most recent call last):
  File "/home/ibrahim/frappe-bench/apps/frappe/frappe/utils/scheduler.py", line 64, in enqueue_events_for_site
    if is_scheduler_inactive():
  File "/home/ibrahim/frappe-bench/apps/frappe/frappe/utils/scheduler.py", line 97, in is_scheduler_inactive
    if is_scheduler_disabled():
  File "/home/ibrahim/frappe-bench/apps/frappe/frappe/utils/scheduler.py", line 106, in is_scheduler_disabled
    return not frappe.utils.cint(frappe.db.get_single_value("System Settings", "enable_scheduler"))
  File "/home/ibrahim/frappe-bench/apps/frappe/frappe/database/database.py", line 559, in get_single_value
    val = self.sql("""select `value` from
  File "/home/ibrahim/frappe-bench/apps/frappe/frappe/database/database.py", line 122, in sql
    self.connect()
  File "/home/ibrahim/frappe-bench/apps/frappe/frappe/database/database.py", line 75, in connect
    self._conn = self.get_connection()
  File "/home/ibrahim/frappe-bench/apps/frappe/frappe/database/mariadb/database.py", line 89, in get_connection
    conn = pymysql.connect(self.host, self.user or '', self.password or '',
  File "/home/ibrahim/frappe-bench/env/lib/python3.8/site-packages/pymysql/__init__.py", line 94, in Connect
    return Connection(*args, **kwargs)
  File "/home/ibrahim/frappe-bench/env/lib/python3.8/site-packages/pymysql/connections.py", line 325, in __init__
    self.connect()
  File "/home/ibrahim/frappe-bench/env/lib/python3.8/site-packages/pymysql/connections.py", line 630, in connect
    raise exc
pymysql.err.OperationalError: (2003, "Can't connect to MySQL server on 'library' ([Errno -3] Temporary failure in name resolution)")

2020-06-16 17:03:42,282 ERROR scheduler Exception in Enqueue Events for Site library
Traceback (most recent call last):
  File "/home/ibrahim/frappe-bench/env/lib/python3.8/site-packages/pymysql/connections.py", line 581, in connect
    sock = socket.create_connection(
  File "/usr/lib/python3.8/socket.py", line 787, in create_connection
    for res in getaddrinfo(host, port, 0, SOCK_STREAM):
  File "/usr/lib/python3.8/socket.py", line 918, in getaddrinfo
    for res in _socket.getaddrinfo(host, port, family, type, proto, flags):
socket.gaierror: [Errno -3] Temporary failure in name resolution

During handling of the above exception, another exception occurred:

Traceback (most recent call last):
  File "/home/ibrahim/frappe-bench/apps/frappe/frappe/utils/scheduler.py", line 64, in enqueue_events_for_site
    if is_scheduler_inactive():
  File "/home/ibrahim/frappe-bench/apps/frappe/frappe/utils/scheduler.py", line 97, in is_scheduler_inactive
    if is_scheduler_disabled():
  File "/home/ibrahim/frappe-bench/apps/frappe/frappe/utils/scheduler.py", line 106, in is_scheduler_disabled
    return not frappe.utils.cint(frappe.db.get_single_value("System Settings", "enable_scheduler"))
  File "/home/ibrahim/frappe-bench/apps/frappe/frappe/database/database.py", line 559, in get_single_value
    val = self.sql("""select `value` from
  File "/home/ibrahim/frappe-bench/apps/frappe/frappe/database/database.py", line 122, in sql
    self.connect()
  File "/home/ibrahim/frappe-bench/apps/frappe/frappe/database/database.py", line 75, in connect
    self._conn = self.get_connection()
  File "/home/ibrahim/frappe-bench/apps/frappe/frappe/database/mariadb/database.py", line 89, in get_connection
    conn = pymysql.connect(self.host, self.user or '', self.password or '',
  File "/home/ibrahim/frappe-bench/env/lib/python3.8/site-packages/pymysql/__init__.py", line 94, in Connect
    return Connection(*args, **kwargs)
  File "/home/ibrahim/frappe-bench/env/lib/python3.8/site-packages/pymysql/connections.py", line 325, in __init__
    self.connect()
  File "/home/ibrahim/frappe-bench/env/lib/python3.8/site-packages/pymysql/connections.py", line 630, in connect
    raise exc
pymysql.err.OperationalError: (2003, "Can't connect to MySQL server on 'library' ([Errno -3] Temporary failure in name resolution)")

2020-06-16 17:03:42,335 ERROR scheduler Exception in Enqueue Events for Site workie
Traceback (most recent call last):
  File "/home/ibrahim/frappe-bench/env/lib/python3.8/site-packages/pymysql/connections.py", line 581, in connect
    sock = socket.create_connection(
  File "/usr/lib/python3.8/socket.py", line 787, in create_connection
    for res in getaddrinfo(host, port, 0, SOCK_STREAM):
  File "/usr/lib/python3.8/socket.py", line 918, in getaddrinfo
    for res in _socket.getaddrinfo(host, port, family, type, proto, flags):
socket.gaierror: [Errno -3] Temporary failure in name resolution

During handling of the above exception, another exception occurred:

Traceback (most recent call last):
  File "/home/ibrahim/frappe-bench/apps/frappe/frappe/utils/scheduler.py", line 64, in enqueue_events_for_site
    if is_scheduler_inactive():
  File "/home/ibrahim/frappe-bench/apps/frappe/frappe/utils/scheduler.py", line 97, in is_scheduler_inactive
    if is_scheduler_disabled():
  File "/home/ibrahim/frappe-bench/apps/frappe/frappe/utils/scheduler.py", line 106, in is_scheduler_disabled
    return not frappe.utils.cint(frappe.db.get_single_value("System Settings", "enable_scheduler"))
  File "/home/ibrahim/frappe-bench/apps/frappe/frappe/database/database.py", line 559, in get_single_value
    val = self.sql("""select `value` from
  File "/home/ibrahim/frappe-bench/apps/frappe/frappe/database/database.py", line 122, in sql
    self.connect()
  File "/home/ibrahim/frappe-bench/apps/frappe/frappe/database/database.py", line 75, in connect
    self._conn = self.get_connection()
  File "/home/ibrahim/frappe-bench/apps/frappe/frappe/database/mariadb/database.py", line 89, in get_connection
    conn = pymysql.connect(self.host, self.user or '', self.password or '',
  File "/home/ibrahim/frappe-bench/env/lib/python3.8/site-packages/pymysql/__init__.py", line 94, in Connect
    return Connection(*args, **kwargs)
  File "/home/ibrahim/frappe-bench/env/lib/python3.8/site-packages/pymysql/connections.py", line 325, in __init__
    self.connect()
  File "/home/ibrahim/frappe-bench/env/lib/python3.8/site-packages/pymysql/connections.py", line 630, in connect
    raise exc
pymysql.err.OperationalError: (2003, "Can't connect to MySQL server on 'library' ([Errno -3] Temporary failure in name resolution)")

2020-06-16 17:04:45,641 ERROR scheduler Exception in Enqueue Events for Site VirtualOffice
Traceback (most recent call last):
  File "/home/ibrahim/frappe-bench/env/lib/python3.8/site-packages/pymysql/connections.py", line 581, in connect
    sock = socket.create_connection(
  File "/usr/lib/python3.8/socket.py", line 787, in create_connection
    for res in getaddrinfo(host, port, 0, SOCK_STREAM):
  File "/usr/lib/python3.8/socket.py", line 918, in getaddrinfo
    for res in _socket.getaddrinfo(host, port, family, type, proto, flags):
socket.gaierror: [Errno -3] Temporary failure in name resolution

During handling of the above exception, another exception occurred:

Traceback (most recent call last):
  File "/home/ibrahim/frappe-bench/apps/frappe/frappe/utils/scheduler.py", line 64, in enqueue_events_for_site
    if is_scheduler_inactive():
  File "/home/ibrahim/frappe-bench/apps/frappe/frappe/utils/scheduler.py", line 97, in is_scheduler_inactive
    if is_scheduler_disabled():
  File "/home/ibrahim/frappe-bench/apps/frappe/frappe/utils/scheduler.py", line 106, in is_scheduler_disabled
    return not frappe.utils.cint(frappe.db.get_single_value("System Settings", "enable_scheduler"))
  File "/home/ibrahim/frappe-bench/apps/frappe/frappe/database/database.py", line 559, in get_single_value
    val = self.sql("""select `value` from
  File "/home/ibrahim/frappe-bench/apps/frappe/frappe/database/database.py", line 122, in sql
    self.connect()
  File "/home/ibrahim/frappe-bench/apps/frappe/frappe/database/database.py", line 75, in connect
    self._conn = self.get_connection()
  File "/home/ibrahim/frappe-bench/apps/frappe/frappe/database/mariadb/database.py", line 89, in get_connection
    conn = pymysql.connect(self.host, self.user or '', self.password or '',
  File "/home/ibrahim/frappe-bench/env/lib/python3.8/site-packages/pymysql/__init__.py", line 94, in Connect
    return Connection(*args, **kwargs)
  File "/home/ibrahim/frappe-bench/env/lib/python3.8/site-packages/pymysql/connections.py", line 325, in __init__
    self.connect()
  File "/home/ibrahim/frappe-bench/env/lib/python3.8/site-packages/pymysql/connections.py", line 630, in connect
    raise exc
pymysql.err.OperationalError: (2003, "Can't connect to MySQL server on 'library' ([Errno -3] Temporary failure in name resolution)")

2020-06-16 17:04:46,392 ERROR scheduler Exception in Enqueue Events for Site library
Traceback (most recent call last):
  File "/home/ibrahim/frappe-bench/env/lib/python3.8/site-packages/pymysql/connections.py", line 581, in connect
    sock = socket.create_connection(
  File "/usr/lib/python3.8/socket.py", line 787, in create_connection
    for res in getaddrinfo(host, port, 0, SOCK_STREAM):
  File "/usr/lib/python3.8/socket.py", line 918, in getaddrinfo
    for res in _socket.getaddrinfo(host, port, family, type, proto, flags):
socket.gaierror: [Errno -3] Temporary failure in name resolution

During handling of the above exception, another exception occurred:

Traceback (most recent call last):
  File "/home/ibrahim/frappe-bench/apps/frappe/frappe/utils/scheduler.py", line 64, in enqueue_events_for_site
    if is_scheduler_inactive():
  File "/home/ibrahim/frappe-bench/apps/frappe/frappe/utils/scheduler.py", line 97, in is_scheduler_inactive
    if is_scheduler_disabled():
  File "/home/ibrahim/frappe-bench/apps/frappe/frappe/utils/scheduler.py", line 106, in is_scheduler_disabled
    return not frappe.utils.cint(frappe.db.get_single_value("System Settings", "enable_scheduler"))
  File "/home/ibrahim/frappe-bench/apps/frappe/frappe/database/database.py", line 559, in get_single_value
    val = self.sql("""select `value` from
  File "/home/ibrahim/frappe-bench/apps/frappe/frappe/database/database.py", line 122, in sql
    self.connect()
  File "/home/ibrahim/frappe-bench/apps/frappe/frappe/database/database.py", line 75, in connect
    self._conn = self.get_connection()
  File "/home/ibrahim/frappe-bench/apps/frappe/frappe/database/mariadb/database.py", line 89, in get_connection
    conn = pymysql.connect(self.host, self.user or '', self.password or '',
  File "/home/ibrahim/frappe-bench/env/lib/python3.8/site-packages/pymysql/__init__.py", line 94, in Connect
    return Connection(*args, **kwargs)
  File "/home/ibrahim/frappe-bench/env/lib/python3.8/site-packages/pymysql/connections.py", line 325, in __init__
    self.connect()
  File "/home/ibrahim/frappe-bench/env/lib/python3.8/site-packages/pymysql/connections.py", line 630, in connect
    raise exc
pymysql.err.OperationalError: (2003, "Can't connect to MySQL server on 'library' ([Errno -3] Temporary failure in name resolution)")

2020-06-16 17:04:47,435 ERROR scheduler Exception in Enqueue Events for Site workie
Traceback (most recent call last):
  File "/home/ibrahim/frappe-bench/env/lib/python3.8/site-packages/pymysql/connections.py", line 581, in connect
    sock = socket.create_connection(
  File "/usr/lib/python3.8/socket.py", line 787, in create_connection
    for res in getaddrinfo(host, port, 0, SOCK_STREAM):
  File "/usr/lib/python3.8/socket.py", line 918, in getaddrinfo
    for res in _socket.getaddrinfo(host, port, family, type, proto, flags):
socket.gaierror: [Errno -3] Temporary failure in name resolution

During handling of the above exception, another exception occurred:

Traceback (most recent call last):
  File "/home/ibrahim/frappe-bench/apps/frappe/frappe/utils/scheduler.py", line 64, in enqueue_events_for_site
    if is_scheduler_inactive():
  File "/home/ibrahim/frappe-bench/apps/frappe/frappe/utils/scheduler.py", line 97, in is_scheduler_inactive
    if is_scheduler_disabled():
  File "/home/ibrahim/frappe-bench/apps/frappe/frappe/utils/scheduler.py", line 106, in is_scheduler_disabled
    return not frappe.utils.cint(frappe.db.get_single_value("System Settings", "enable_scheduler"))
  File "/home/ibrahim/frappe-bench/apps/frappe/frappe/database/database.py", line 559, in get_single_value
    val = self.sql("""select `value` from
  File "/home/ibrahim/frappe-bench/apps/frappe/frappe/database/database.py", line 122, in sql
    self.connect()
  File "/home/ibrahim/frappe-bench/apps/frappe/frappe/database/database.py", line 75, in connect
    self._conn = self.get_connection()
  File "/home/ibrahim/frappe-bench/apps/frappe/frappe/database/mariadb/database.py", line 89, in get_connection
    conn = pymysql.connect(self.host, self.user or '', self.password or '',
  File "/home/ibrahim/frappe-bench/env/lib/python3.8/site-packages/pymysql/__init__.py", line 94, in Connect
    return Connection(*args, **kwargs)
  File "/home/ibrahim/frappe-bench/env/lib/python3.8/site-packages/pymysql/connections.py", line 325, in __init__
    self.connect()
  File "/home/ibrahim/frappe-bench/env/lib/python3.8/site-packages/pymysql/connections.py", line 630, in connect
    raise exc
pymysql.err.OperationalError: (2003, "Can't connect to MySQL server on 'library' ([Errno -3] Temporary failure in name resolution)")

2020-06-16 17:05:47,496 ERROR scheduler Exception in Enqueue Events for Site VirtualOffice
Traceback (most recent call last):
  File "/home/ibrahim/frappe-bench/env/lib/python3.8/site-packages/pymysql/connections.py", line 581, in connect
    sock = socket.create_connection(
  File "/usr/lib/python3.8/socket.py", line 787, in create_connection
    for res in getaddrinfo(host, port, 0, SOCK_STREAM):
  File "/usr/lib/python3.8/socket.py", line 918, in getaddrinfo
    for res in _socket.getaddrinfo(host, port, family, type, proto, flags):
socket.gaierror: [Errno -3] Temporary failure in name resolution

During handling of the above exception, another exception occurred:

Traceback (most recent call last):
  File "/home/ibrahim/frappe-bench/apps/frappe/frappe/utils/scheduler.py", line 64, in enqueue_events_for_site
    if is_scheduler_inactive():
  File "/home/ibrahim/frappe-bench/apps/frappe/frappe/utils/scheduler.py", line 97, in is_scheduler_inactive
    if is_scheduler_disabled():
  File "/home/ibrahim/frappe-bench/apps/frappe/frappe/utils/scheduler.py", line 106, in is_scheduler_disabled
    return not frappe.utils.cint(frappe.db.get_single_value("System Settings", "enable_scheduler"))
  File "/home/ibrahim/frappe-bench/apps/frappe/frappe/database/database.py", line 559, in get_single_value
    val = self.sql("""select `value` from
  File "/home/ibrahim/frappe-bench/apps/frappe/frappe/database/database.py", line 122, in sql
    self.connect()
  File "/home/ibrahim/frappe-bench/apps/frappe/frappe/database/database.py", line 75, in connect
    self._conn = self.get_connection()
  File "/home/ibrahim/frappe-bench/apps/frappe/frappe/database/mariadb/database.py", line 89, in get_connection
    conn = pymysql.connect(self.host, self.user or '', self.password or '',
  File "/home/ibrahim/frappe-bench/env/lib/python3.8/site-packages/pymysql/__init__.py", line 94, in Connect
    return Connection(*args, **kwargs)
  File "/home/ibrahim/frappe-bench/env/lib/python3.8/site-packages/pymysql/connections.py", line 325, in __init__
    self.connect()
  File "/home/ibrahim/frappe-bench/env/lib/python3.8/site-packages/pymysql/connections.py", line 630, in connect
    raise exc
pymysql.err.OperationalError: (2003, "Can't connect to MySQL server on 'library' ([Errno -3] Temporary failure in name resolution)")

2020-06-16 17:05:47,498 ERROR scheduler Exception in Enqueue Events for Site library
Traceback (most recent call last):
  File "/home/ibrahim/frappe-bench/env/lib/python3.8/site-packages/pymysql/connections.py", line 581, in connect
    sock = socket.create_connection(
  File "/usr/lib/python3.8/socket.py", line 787, in create_connection
    for res in getaddrinfo(host, port, 0, SOCK_STREAM):
  File "/usr/lib/python3.8/socket.py", line 918, in getaddrinfo
    for res in _socket.getaddrinfo(host, port, family, type, proto, flags):
socket.gaierror: [Errno -3] Temporary failure in name resolution

During handling of the above exception, another exception occurred:

Traceback (most recent call last):
  File "/home/ibrahim/frappe-bench/apps/frappe/frappe/utils/scheduler.py", line 64, in enqueue_events_for_site
    if is_scheduler_inactive():
  File "/home/ibrahim/frappe-bench/apps/frappe/frappe/utils/scheduler.py", line 97, in is_scheduler_inactive
    if is_scheduler_disabled():
  File "/home/ibrahim/frappe-bench/apps/frappe/frappe/utils/scheduler.py", line 106, in is_scheduler_disabled
    return not frappe.utils.cint(frappe.db.get_single_value("System Settings", "enable_scheduler"))
  File "/home/ibrahim/frappe-bench/apps/frappe/frappe/database/database.py", line 559, in get_single_value
    val = self.sql("""select `value` from
  File "/home/ibrahim/frappe-bench/apps/frappe/frappe/database/database.py", line 122, in sql
    self.connect()
  File "/home/ibrahim/frappe-bench/apps/frappe/frappe/database/database.py", line 75, in connect
    self._conn = self.get_connection()
  File "/home/ibrahim/frappe-bench/apps/frappe/frappe/database/mariadb/database.py", line 89, in get_connection
    conn = pymysql.connect(self.host, self.user or '', self.password or '',
  File "/home/ibrahim/frappe-bench/env/lib/python3.8/site-packages/pymysql/__init__.py", line 94, in Connect
    return Connection(*args, **kwargs)
  File "/home/ibrahim/frappe-bench/env/lib/python3.8/site-packages/pymysql/connections.py", line 325, in __init__
    self.connect()
  File "/home/ibrahim/frappe-bench/env/lib/python3.8/site-packages/pymysql/connections.py", line 630, in connect
    raise exc
pymysql.err.OperationalError: (2003, "Can't connect to MySQL server on 'library' ([Errno -3] Temporary failure in name resolution)")

2020-06-16 17:05:47,499 ERROR scheduler Exception in Enqueue Events for Site workie
Traceback (most recent call last):
  File "/home/ibrahim/frappe-bench/env/lib/python3.8/site-packages/pymysql/connections.py", line 581, in connect
    sock = socket.create_connection(
  File "/usr/lib/python3.8/socket.py", line 787, in create_connection
    for res in getaddrinfo(host, port, 0, SOCK_STREAM):
  File "/usr/lib/python3.8/socket.py", line 918, in getaddrinfo
    for res in _socket.getaddrinfo(host, port, family, type, proto, flags):
socket.gaierror: [Errno -3] Temporary failure in name resolution

During handling of the above exception, another exception occurred:

Traceback (most recent call last):
  File "/home/ibrahim/frappe-bench/apps/frappe/frappe/utils/scheduler.py", line 64, in enqueue_events_for_site
    if is_scheduler_inactive():
  File "/home/ibrahim/frappe-bench/apps/frappe/frappe/utils/scheduler.py", line 97, in is_scheduler_inactive
    if is_scheduler_disabled():
  File "/home/ibrahim/frappe-bench/apps/frappe/frappe/utils/scheduler.py", line 106, in is_scheduler_disabled
    return not frappe.utils.cint(frappe.db.get_single_value("System Settings", "enable_scheduler"))
  File "/home/ibrahim/frappe-bench/apps/frappe/frappe/database/database.py", line 559, in get_single_value
    val = self.sql("""select `value` from
  File "/home/ibrahim/frappe-bench/apps/frappe/frappe/database/database.py", line 122, in sql
    self.connect()
  File "/home/ibrahim/frappe-bench/apps/frappe/frappe/database/database.py", line 75, in connect
    self._conn = self.get_connection()
  File "/home/ibrahim/frappe-bench/apps/frappe/frappe/database/mariadb/database.py", line 89, in get_connection
    conn = pymysql.connect(self.host, self.user or '', self.password or '',
  File "/home/ibrahim/frappe-bench/env/lib/python3.8/site-packages/pymysql/__init__.py", line 94, in Connect
    return Connection(*args, **kwargs)
  File "/home/ibrahim/frappe-bench/env/lib/python3.8/site-packages/pymysql/connections.py", line 325, in __init__
    self.connect()
  File "/home/ibrahim/frappe-bench/env/lib/python3.8/site-packages/pymysql/connections.py", line 630, in connect
    raise exc
pymysql.err.OperationalError: (2003, "Can't connect to MySQL server on 'library' ([Errno -3] Temporary failure in name resolution)")

2020-06-16 17:06:49,118 ERROR scheduler Exception in Enqueue Events for Site VirtualOffice
Traceback (most recent call last):
  File "/home/ibrahim/frappe-bench/env/lib/python3.8/site-packages/pymysql/connections.py", line 581, in connect
    sock = socket.create_connection(
  File "/usr/lib/python3.8/socket.py", line 787, in create_connection
    for res in getaddrinfo(host, port, 0, SOCK_STREAM):
  File "/usr/lib/python3.8/socket.py", line 918, in getaddrinfo
    for res in _socket.getaddrinfo(host, port, family, type, proto, flags):
socket.gaierror: [Errno -3] Temporary failure in name resolution

During handling of the above exception, another exception occurred:

Traceback (most recent call last):
  File "/home/ibrahim/frappe-bench/apps/frappe/frappe/utils/scheduler.py", line 64, in enqueue_events_for_site
    if is_scheduler_inactive():
  File "/home/ibrahim/frappe-bench/apps/frappe/frappe/utils/scheduler.py", line 97, in is_scheduler_inactive
    if is_scheduler_disabled():
  File "/home/ibrahim/frappe-bench/apps/frappe/frappe/utils/scheduler.py", line 106, in is_scheduler_disabled
    return not frappe.utils.cint(frappe.db.get_single_value("System Settings", "enable_scheduler"))
  File "/home/ibrahim/frappe-bench/apps/frappe/frappe/database/database.py", line 559, in get_single_value
    val = self.sql("""select `value` from
  File "/home/ibrahim/frappe-bench/apps/frappe/frappe/database/database.py", line 122, in sql
    self.connect()
  File "/home/ibrahim/frappe-bench/apps/frappe/frappe/database/database.py", line 75, in connect
    self._conn = self.get_connection()
  File "/home/ibrahim/frappe-bench/apps/frappe/frappe/database/mariadb/database.py", line 89, in get_connection
    conn = pymysql.connect(self.host, self.user or '', self.password or '',
  File "/home/ibrahim/frappe-bench/env/lib/python3.8/site-packages/pymysql/__init__.py", line 94, in Connect
    return Connection(*args, **kwargs)
  File "/home/ibrahim/frappe-bench/env/lib/python3.8/site-packages/pymysql/connections.py", line 325, in __init__
    self.connect()
  File "/home/ibrahim/frappe-bench/env/lib/python3.8/site-packages/pymysql/connections.py", line 630, in connect
    raise exc
pymysql.err.OperationalError: (2003, "Can't connect to MySQL server on 'library' ([Errno -3] Temporary failure in name resolution)")

2020-06-16 17:06:49,211 ERROR scheduler Exception in Enqueue Events for Site library
Traceback (most recent call last):
  File "/home/ibrahim/frappe-bench/env/lib/python3.8/site-packages/pymysql/connections.py", line 581, in connect
    sock = socket.create_connection(
  File "/usr/lib/python3.8/socket.py", line 787, in create_connection
    for res in getaddrinfo(host, port, 0, SOCK_STREAM):
  File "/usr/lib/python3.8/socket.py", line 918, in getaddrinfo
    for res in _socket.getaddrinfo(host, port, family, type, proto, flags):
socket.gaierror: [Errno -3] Temporary failure in name resolution

During handling of the above exception, another exception occurred:

Traceback (most recent call last):
  File "/home/ibrahim/frappe-bench/apps/frappe/frappe/utils/scheduler.py", line 64, in enqueue_events_for_site
    if is_scheduler_inactive():
  File "/home/ibrahim/frappe-bench/apps/frappe/frappe/utils/scheduler.py", line 97, in is_scheduler_inactive
    if is_scheduler_disabled():
  File "/home/ibrahim/frappe-bench/apps/frappe/frappe/utils/scheduler.py", line 106, in is_scheduler_disabled
    return not frappe.utils.cint(frappe.db.get_single_value("System Settings", "enable_scheduler"))
  File "/home/ibrahim/frappe-bench/apps/frappe/frappe/database/database.py", line 559, in get_single_value
    val = self.sql("""select `value` from
  File "/home/ibrahim/frappe-bench/apps/frappe/frappe/database/database.py", line 122, in sql
    self.connect()
  File "/home/ibrahim/frappe-bench/apps/frappe/frappe/database/database.py", line 75, in connect
    self._conn = self.get_connection()
  File "/home/ibrahim/frappe-bench/apps/frappe/frappe/database/mariadb/database.py", line 89, in get_connection
    conn = pymysql.connect(self.host, self.user or '', self.password or '',
  File "/home/ibrahim/frappe-bench/env/lib/python3.8/site-packages/pymysql/__init__.py", line 94, in Connect
    return Connection(*args, **kwargs)
  File "/home/ibrahim/frappe-bench/env/lib/python3.8/site-packages/pymysql/connections.py", line 325, in __init__
    self.connect()
  File "/home/ibrahim/frappe-bench/env/lib/python3.8/site-packages/pymysql/connections.py", line 630, in connect
    raise exc
pymysql.err.OperationalError: (2003, "Can't connect to MySQL server on 'library' ([Errno -3] Temporary failure in name resolution)")

2020-06-16 17:06:49,236 ERROR scheduler Exception in Enqueue Events for Site workie
Traceback (most recent call last):
  File "/home/ibrahim/frappe-bench/env/lib/python3.8/site-packages/pymysql/connections.py", line 581, in connect
    sock = socket.create_connection(
  File "/usr/lib/python3.8/socket.py", line 787, in create_connection
    for res in getaddrinfo(host, port, 0, SOCK_STREAM):
  File "/usr/lib/python3.8/socket.py", line 918, in getaddrinfo
    for res in _socket.getaddrinfo(host, port, family, type, proto, flags):
socket.gaierror: [Errno -3] Temporary failure in name resolution

During handling of the above exception, another exception occurred:

Traceback (most recent call last):
  File "/home/ibrahim/frappe-bench/apps/frappe/frappe/utils/scheduler.py", line 64, in enqueue_events_for_site
    if is_scheduler_inactive():
  File "/home/ibrahim/frappe-bench/apps/frappe/frappe/utils/scheduler.py", line 97, in is_scheduler_inactive
    if is_scheduler_disabled():
  File "/home/ibrahim/frappe-bench/apps/frappe/frappe/utils/scheduler.py", line 106, in is_scheduler_disabled
    return not frappe.utils.cint(frappe.db.get_single_value("System Settings", "enable_scheduler"))
  File "/home/ibrahim/frappe-bench/apps/frappe/frappe/database/database.py", line 559, in get_single_value
    val = self.sql("""select `value` from
  File "/home/ibrahim/frappe-bench/apps/frappe/frappe/database/database.py", line 122, in sql
    self.connect()
  File "/home/ibrahim/frappe-bench/apps/frappe/frappe/database/database.py", line 75, in connect
    self._conn = self.get_connection()
  File "/home/ibrahim/frappe-bench/apps/frappe/frappe/database/mariadb/database.py", line 89, in get_connection
    conn = pymysql.connect(self.host, self.user or '', self.password or '',
  File "/home/ibrahim/frappe-bench/env/lib/python3.8/site-packages/pymysql/__init__.py", line 94, in Connect
    return Connection(*args, **kwargs)
  File "/home/ibrahim/frappe-bench/env/lib/python3.8/site-packages/pymysql/connections.py", line 325, in __init__
    self.connect()
  File "/home/ibrahim/frappe-bench/env/lib/python3.8/site-packages/pymysql/connections.py", line 630, in connect
    raise exc
pymysql.err.OperationalError: (2003, "Can't connect to MySQL server on 'library' ([Errno -3] Temporary failure in name resolution)")

2020-06-16 17:07:50,095 ERROR scheduler Exception in Enqueue Events for Site VirtualOffice
Traceback (most recent call last):
  File "/home/ibrahim/frappe-bench/env/lib/python3.8/site-packages/pymysql/connections.py", line 581, in connect
    sock = socket.create_connection(
  File "/usr/lib/python3.8/socket.py", line 787, in create_connection
    for res in getaddrinfo(host, port, 0, SOCK_STREAM):
  File "/usr/lib/python3.8/socket.py", line 918, in getaddrinfo
    for res in _socket.getaddrinfo(host, port, family, type, proto, flags):
socket.gaierror: [Errno -3] Temporary failure in name resolution

During handling of the above exception, another exception occurred:

Traceback (most recent call last):
  File "/home/ibrahim/frappe-bench/apps/frappe/frappe/utils/scheduler.py", line 64, in enqueue_events_for_site
    if is_scheduler_inactive():
  File "/home/ibrahim/frappe-bench/apps/frappe/frappe/utils/scheduler.py", line 97, in is_scheduler_inactive
    if is_scheduler_disabled():
  File "/home/ibrahim/frappe-bench/apps/frappe/frappe/utils/scheduler.py", line 106, in is_scheduler_disabled
    return not frappe.utils.cint(frappe.db.get_single_value("System Settings", "enable_scheduler"))
  File "/home/ibrahim/frappe-bench/apps/frappe/frappe/database/database.py", line 559, in get_single_value
    val = self.sql("""select `value` from
  File "/home/ibrahim/frappe-bench/apps/frappe/frappe/database/database.py", line 122, in sql
    self.connect()
  File "/home/ibrahim/frappe-bench/apps/frappe/frappe/database/database.py", line 75, in connect
    self._conn = self.get_connection()
  File "/home/ibrahim/frappe-bench/apps/frappe/frappe/database/mariadb/database.py", line 89, in get_connection
    conn = pymysql.connect(self.host, self.user or '', self.password or '',
  File "/home/ibrahim/frappe-bench/env/lib/python3.8/site-packages/pymysql/__init__.py", line 94, in Connect
    return Connection(*args, **kwargs)
  File "/home/ibrahim/frappe-bench/env/lib/python3.8/site-packages/pymysql/connections.py", line 325, in __init__
    self.connect()
  File "/home/ibrahim/frappe-bench/env/lib/python3.8/site-packages/pymysql/connections.py", line 630, in connect
    raise exc
pymysql.err.OperationalError: (2003, "Can't connect to MySQL server on 'library' ([Errno -3] Temporary failure in name resolution)")

2020-06-16 17:07:50,319 ERROR scheduler Exception in Enqueue Events for Site library
Traceback (most recent call last):
  File "/home/ibrahim/frappe-bench/env/lib/python3.8/site-packages/pymysql/connections.py", line 581, in connect
    sock = socket.create_connection(
  File "/usr/lib/python3.8/socket.py", line 787, in create_connection
    for res in getaddrinfo(host, port, 0, SOCK_STREAM):
  File "/usr/lib/python3.8/socket.py", line 918, in getaddrinfo
    for res in _socket.getaddrinfo(host, port, family, type, proto, flags):
socket.gaierror: [Errno -3] Temporary failure in name resolution

During handling of the above exception, another exception occurred:

Traceback (most recent call last):
  File "/home/ibrahim/frappe-bench/apps/frappe/frappe/utils/scheduler.py", line 64, in enqueue_events_for_site
    if is_scheduler_inactive():
  File "/home/ibrahim/frappe-bench/apps/frappe/frappe/utils/scheduler.py", line 97, in is_scheduler_inactive
    if is_scheduler_disabled():
  File "/home/ibrahim/frappe-bench/apps/frappe/frappe/utils/scheduler.py", line 106, in is_scheduler_disabled
    return not frappe.utils.cint(frappe.db.get_single_value("System Settings", "enable_scheduler"))
  File "/home/ibrahim/frappe-bench/apps/frappe/frappe/database/database.py", line 559, in get_single_value
    val = self.sql("""select `value` from
  File "/home/ibrahim/frappe-bench/apps/frappe/frappe/database/database.py", line 122, in sql
    self.connect()
  File "/home/ibrahim/frappe-bench/apps/frappe/frappe/database/database.py", line 75, in connect
    self._conn = self.get_connection()
  File "/home/ibrahim/frappe-bench/apps/frappe/frappe/database/mariadb/database.py", line 89, in get_connection
    conn = pymysql.connect(self.host, self.user or '', self.password or '',
  File "/home/ibrahim/frappe-bench/env/lib/python3.8/site-packages/pymysql/__init__.py", line 94, in Connect
    return Connection(*args, **kwargs)
  File "/home/ibrahim/frappe-bench/env/lib/python3.8/site-packages/pymysql/connections.py", line 325, in __init__
    self.connect()
  File "/home/ibrahim/frappe-bench/env/lib/python3.8/site-packages/pymysql/connections.py", line 630, in connect
    raise exc
pymysql.err.OperationalError: (2003, "Can't connect to MySQL server on 'library' ([Errno -3] Temporary failure in name resolution)")

2020-06-16 17:07:50,355 ERROR scheduler Exception in Enqueue Events for Site workie
Traceback (most recent call last):
  File "/home/ibrahim/frappe-bench/env/lib/python3.8/site-packages/pymysql/connections.py", line 581, in connect
    sock = socket.create_connection(
  File "/usr/lib/python3.8/socket.py", line 787, in create_connection
    for res in getaddrinfo(host, port, 0, SOCK_STREAM):
  File "/usr/lib/python3.8/socket.py", line 918, in getaddrinfo
    for res in _socket.getaddrinfo(host, port, family, type, proto, flags):
socket.gaierror: [Errno -3] Temporary failure in name resolution

During handling of the above exception, another exception occurred:

Traceback (most recent call last):
  File "/home/ibrahim/frappe-bench/apps/frappe/frappe/utils/scheduler.py", line 64, in enqueue_events_for_site
    if is_scheduler_inactive():
  File "/home/ibrahim/frappe-bench/apps/frappe/frappe/utils/scheduler.py", line 97, in is_scheduler_inactive
    if is_scheduler_disabled():
  File "/home/ibrahim/frappe-bench/apps/frappe/frappe/utils/scheduler.py", line 106, in is_scheduler_disabled
    return not frappe.utils.cint(frappe.db.get_single_value("System Settings", "enable_scheduler"))
  File "/home/ibrahim/frappe-bench/apps/frappe/frappe/database/database.py", line 559, in get_single_value
    val = self.sql("""select `value` from
  File "/home/ibrahim/frappe-bench/apps/frappe/frappe/database/database.py", line 122, in sql
    self.connect()
  File "/home/ibrahim/frappe-bench/apps/frappe/frappe/database/database.py", line 75, in connect
    self._conn = self.get_connection()
  File "/home/ibrahim/frappe-bench/apps/frappe/frappe/database/mariadb/database.py", line 89, in get_connection
    conn = pymysql.connect(self.host, self.user or '', self.password or '',
  File "/home/ibrahim/frappe-bench/env/lib/python3.8/site-packages/pymysql/__init__.py", line 94, in Connect
    return Connection(*args, **kwargs)
  File "/home/ibrahim/frappe-bench/env/lib/python3.8/site-packages/pymysql/connections.py", line 325, in __init__
    self.connect()
  File "/home/ibrahim/frappe-bench/env/lib/python3.8/site-packages/pymysql/connections.py", line 630, in connect
    raise exc
pymysql.err.OperationalError: (2003, "Can't connect to MySQL server on 'library' ([Errno -3] Temporary failure in name resolution)")

2020-06-16 17:08:54,525 ERROR scheduler Exception in Enqueue Events for Site VirtualOffice
Traceback (most recent call last):
  File "/home/ibrahim/frappe-bench/env/lib/python3.8/site-packages/pymysql/connections.py", line 581, in connect
    sock = socket.create_connection(
  File "/usr/lib/python3.8/socket.py", line 787, in create_connection
    for res in getaddrinfo(host, port, 0, SOCK_STREAM):
  File "/usr/lib/python3.8/socket.py", line 918, in getaddrinfo
    for res in _socket.getaddrinfo(host, port, family, type, proto, flags):
socket.gaierror: [Errno -3] Temporary failure in name resolution

During handling of the above exception, another exception occurred:

Traceback (most recent call last):
  File "/home/ibrahim/frappe-bench/apps/frappe/frappe/utils/scheduler.py", line 64, in enqueue_events_for_site
    if is_scheduler_inactive():
  File "/home/ibrahim/frappe-bench/apps/frappe/frappe/utils/scheduler.py", line 97, in is_scheduler_inactive
    if is_scheduler_disabled():
  File "/home/ibrahim/frappe-bench/apps/frappe/frappe/utils/scheduler.py", line 106, in is_scheduler_disabled
    return not frappe.utils.cint(frappe.db.get_single_value("System Settings", "enable_scheduler"))
  File "/home/ibrahim/frappe-bench/apps/frappe/frappe/database/database.py", line 559, in get_single_value
    val = self.sql("""select `value` from
  File "/home/ibrahim/frappe-bench/apps/frappe/frappe/database/database.py", line 122, in sql
    self.connect()
  File "/home/ibrahim/frappe-bench/apps/frappe/frappe/database/database.py", line 75, in connect
    self._conn = self.get_connection()
  File "/home/ibrahim/frappe-bench/apps/frappe/frappe/database/mariadb/database.py", line 89, in get_connection
    conn = pymysql.connect(self.host, self.user or '', self.password or '',
  File "/home/ibrahim/frappe-bench/env/lib/python3.8/site-packages/pymysql/__init__.py", line 94, in Connect
    return Connection(*args, **kwargs)
  File "/home/ibrahim/frappe-bench/env/lib/python3.8/site-packages/pymysql/connections.py", line 325, in __init__
    self.connect()
  File "/home/ibrahim/frappe-bench/env/lib/python3.8/site-packages/pymysql/connections.py", line 630, in connect
    raise exc
pymysql.err.OperationalError: (2003, "Can't connect to MySQL server on 'library' ([Errno -3] Temporary failure in name resolution)")

